2023-01-05 14:40:57,637 WARNING Not Found: /appeal/<%= BASE_URL %>favicon.ico
2023-01-05 14:40:57,638 WARNING "GET /appeal/%3C%=%20BASE_URL%20%%3Efavicon.ico HTTP/1.1" 404 5872
2023-01-05 14:46:14,411 ERROR Internal Server Error: /appeal/
Traceback (most recent call last):
  File "/Library/Frameworks/Python.framework/Versions/3.10/lib/python3.10/site-packages/django/core/handlers/exception.py", line 55, in inner
    response = get_response(request)
  File "/Library/Frameworks/Python.framework/Versions/3.10/lib/python3.10/site-packages/django/core/handlers/base.py", line 220, in _get_response
    response = response.render()
  File "/Library/Frameworks/Python.framework/Versions/3.10/lib/python3.10/site-packages/django/template/response.py", line 114, in render
    self.content = self.rendered_content
  File "/Library/Frameworks/Python.framework/Versions/3.10/lib/python3.10/site-packages/django/template/response.py", line 92, in rendered_content
    return template.render(context, self._request)
  File "/Library/Frameworks/Python.framework/Versions/3.10/lib/python3.10/site-packages/django/template/backends/django.py", line 62, in render
    return self.template.render(context)
  File "/Library/Frameworks/Python.framework/Versions/3.10/lib/python3.10/site-packages/django/template/base.py", line 175, in render
    return self._render(context)
  File "/Library/Frameworks/Python.framework/Versions/3.10/lib/python3.10/site-packages/django/template/base.py", line 167, in _render
    return self.nodelist.render(context)
  File "/Library/Frameworks/Python.framework/Versions/3.10/lib/python3.10/site-packages/django/template/base.py", line 1000, in render
    return SafeString("".join([node.render_annotated(context) for node in self]))
  File "/Library/Frameworks/Python.framework/Versions/3.10/lib/python3.10/site-packages/django/template/base.py", line 1000, in <listcomp>
    return SafeString("".join([node.render_annotated(context) for node in self]))
  File "/Library/Frameworks/Python.framework/Versions/3.10/lib/python3.10/site-packages/django/template/base.py", line 958, in render_annotated
    return self.render(context)
  File "/Library/Frameworks/Python.framework/Versions/3.10/lib/python3.10/site-packages/django/template/library.py", line 239, in render
    output = self.func(*resolved_args, **resolved_kwargs)
  File "/Library/Frameworks/Python.framework/Versions/3.10/lib/python3.10/site-packages/webpack_loader/templatetags/webpack_loader.py", line 12, in render_bundle
    tags = utils.get_as_tags(bundle_name, extension=extension, config=config, attrs=attrs)
  File "/Library/Frameworks/Python.framework/Versions/3.10/lib/python3.10/site-packages/webpack_loader/utils.py", line 62, in get_as_tags
    bundle = _get_bundle(bundle_name, extension, config)
  File "/Library/Frameworks/Python.framework/Versions/3.10/lib/python3.10/site-packages/webpack_loader/utils.py", line 40, in _get_bundle
    bundle = get_loader(config).get_bundle(bundle_name)
  File "/Library/Frameworks/Python.framework/Versions/3.10/lib/python3.10/site-packages/webpack_loader/loader.py", line 96, in get_bundle
    raise WebpackError(error)
webpack_loader.exceptions.WebpackError: 
            ESLintError in 
            [eslint] 
/Users/deniskanukov/online_reception_of_appeals/mysite/frontend/src/components/DragndropTable.vue
  51:7  error  Duplicated key 'newTicketsProp'     vue/no-dupe-keys
  52:7  error  Duplicated key 'inProgressTickets'  vue/no-dupe-keys
  53:7  error  Duplicated key 'closedTickets'      vue/no-dupe-keys

âœ– 3 problems (3 errors, 0 warnings)

            
2023-01-05 14:46:14,439 ERROR "GET /appeal/ HTTP/1.1" 500 122187
2023-01-05 14:48:07,657 ERROR Internal Server Error: /appeal/
Traceback (most recent call last):
  File "/Library/Frameworks/Python.framework/Versions/3.10/lib/python3.10/site-packages/django/core/handlers/exception.py", line 55, in inner
    response = get_response(request)
  File "/Library/Frameworks/Python.framework/Versions/3.10/lib/python3.10/site-packages/django/core/handlers/base.py", line 220, in _get_response
    response = response.render()
  File "/Library/Frameworks/Python.framework/Versions/3.10/lib/python3.10/site-packages/django/template/response.py", line 114, in render
    self.content = self.rendered_content
  File "/Library/Frameworks/Python.framework/Versions/3.10/lib/python3.10/site-packages/django/template/response.py", line 92, in rendered_content
    return template.render(context, self._request)
  File "/Library/Frameworks/Python.framework/Versions/3.10/lib/python3.10/site-packages/django/template/backends/django.py", line 62, in render
    return self.template.render(context)
  File "/Library/Frameworks/Python.framework/Versions/3.10/lib/python3.10/site-packages/django/template/base.py", line 175, in render
    return self._render(context)
  File "/Library/Frameworks/Python.framework/Versions/3.10/lib/python3.10/site-packages/django/template/base.py", line 167, in _render
    return self.nodelist.render(context)
  File "/Library/Frameworks/Python.framework/Versions/3.10/lib/python3.10/site-packages/django/template/base.py", line 1000, in render
    return SafeString("".join([node.render_annotated(context) for node in self]))
  File "/Library/Frameworks/Python.framework/Versions/3.10/lib/python3.10/site-packages/django/template/base.py", line 1000, in <listcomp>
    return SafeString("".join([node.render_annotated(context) for node in self]))
  File "/Library/Frameworks/Python.framework/Versions/3.10/lib/python3.10/site-packages/django/template/base.py", line 958, in render_annotated
    return self.render(context)
  File "/Library/Frameworks/Python.framework/Versions/3.10/lib/python3.10/site-packages/django/template/library.py", line 239, in render
    output = self.func(*resolved_args, **resolved_kwargs)
  File "/Library/Frameworks/Python.framework/Versions/3.10/lib/python3.10/site-packages/webpack_loader/templatetags/webpack_loader.py", line 12, in render_bundle
    tags = utils.get_as_tags(bundle_name, extension=extension, config=config, attrs=attrs)
  File "/Library/Frameworks/Python.framework/Versions/3.10/lib/python3.10/site-packages/webpack_loader/utils.py", line 62, in get_as_tags
    bundle = _get_bundle(bundle_name, extension, config)
  File "/Library/Frameworks/Python.framework/Versions/3.10/lib/python3.10/site-packages/webpack_loader/utils.py", line 40, in _get_bundle
    bundle = get_loader(config).get_bundle(bundle_name)
  File "/Library/Frameworks/Python.framework/Versions/3.10/lib/python3.10/site-packages/webpack_loader/loader.py", line 96, in get_bundle
    raise WebpackError(error)
webpack_loader.exceptions.WebpackError: 
            ModuleBuildError in 
            Module build failed (from ./node_modules/babel-loader/lib/index.js):
SyntaxError: /Users/deniskanukov/online_reception_of_appeals/mysite/frontend/src/components/DragndropTable.vue: Unexpected token (14:61)

  12 |   data() {
  13 |     return {
> 14 |       newTicketsProp: this.tickets.filter((ticket) => ticket.),
     |                                                              ^
  15 |       inProgressTickets: [],
  16 |       closedTickets: [],
  17 |     }
    at instantiate (/Users/deniskanukov/online_reception_of_appeals/mysite/frontend/node_modules/@babel/parser/lib/index.js:67:32)
    at constructor (/Users/deniskanukov/online_reception_of_appeals/mysite/frontend/node_modules/@babel/parser/lib/index.js:364:12)
    at JSXParserMixin.raise (/Users/deniskanukov/online_reception_of_appeals/mysite/frontend/node_modules/@babel/parser/lib/index.js:3364:19)
    at JSXParserMixin.unexpected (/Users/deniskanukov/online_reception_of_appeals/mysite/frontend/node_modules/@babel/parser/lib/index.js:3397:16)
    at JSXParserMixin.parseIdentifierName (/Users/deniskanukov/online_reception_of_appeals/mysite/frontend/node_modules/@babel/parser/lib/index.js:12404:18)
    at JSXParserMixin.parseIdentifier (/Users/deniskanukov/online_reception_of_appeals/mysite/frontend/node_modules/@babel/parser/lib/index.js:12387:23)
    at JSXParserMixin.parseMember (/Users/deniskanukov/online_reception_of_appeals/mysite/frontend/node_modules/@babel/parser/lib/index.js:11238:28)
    at JSXParserMixin.parseSubscript (/Users/deniskanukov/online_reception_of_appeals/mysite/frontend/node_modules/@babel/parser/lib/index.js:11214:21)
    at JSXParserMixin.parseSubscripts (/Users/deniskanukov/online_reception_of_appeals/mysite/frontend/node_modules/@babel/parser/lib/index.js:11184:19)
    at JSXParserMixin.parseExprSubscripts (/Users/deniskanukov/online_reception_of_appeals/mysite/frontend/node_modules/@babel/parser/lib/index.js:11175:17)
    at JSXParserMixin.parseUpdate (/Users/deniskanukov/online_reception_of_appeals/mysite/frontend/node_modules/@babel/parser/lib/index.js:11153:21)
    at JSXParserMixin.parseMaybeUnary (/Users/deniskanukov/online_reception_of_appeals/mysite/frontend/node_modules/@babel/parser/lib/index.js:11127:23)
    at JSXParserMixin.parseMaybeUnaryOrPrivate (/Users/deniskanukov/online_reception_of_appeals/mysite/frontend/node_modules/@babel/parser/lib/index.js:10956:61)
    at JSXParserMixin.parseExprOps (/Users/deniskanukov/online_reception_of_appeals/mysite/frontend/node_modules/@babel/parser/lib/index.js:10962:23)
    at JSXParserMixin.parseMaybeConditional (/Users/deniskanukov/online_reception_of_appeals/mysite/frontend/node_modules/@babel/parser/lib/index.js:10937:23)
    at JSXParserMixin.parseMaybeAssign (/Users/deniskanukov/online_reception_of_appeals/mysite/frontend/node_modules/@babel/parser/lib/index.js:10895:21)
    at JSXParserMixin.parseFunctionBody (/Users/deniskanukov/online_reception_of_appeals/mysite/frontend/node_modules/@babel/parser/lib/index.js:12279:24)
    at JSXParserMixin.parseArrowExpression (/Users/deniskanukov/online_reception_of_appeals/mysite/frontend/node_modules/@babel/parser/lib/index.js:12260:10)
    at JSXParserMixin.parseParenAndDistinguishExpression (/Users/deniskanukov/online_reception_of_appeals/mysite/frontend/node_modules/@babel/parser/lib/index.js:11829:12)
    at JSXParserMixin.parseExprAtom (/Users/deniskanukov/online_reception_of_appeals/mysite/frontend/node_modules/@babel/parser/lib/index.js:11446:23)
    at JSXParserMixin.parseExprAtom (/Users/deniskanukov/online_reception_of_appeals/mysite/frontend/node_modules/@babel/parser/lib/index.js:7238:20)
    at JSXParserMixin.parseExprSubscripts (/Users/deniskanukov/online_reception_of_appeals/mysite/frontend/node_modules/@babel/parser/lib/index.js:11171:23)
    at JSXParserMixin.parseUpdate (/Users/deniskanukov/online_reception_of_appeals/mysite/frontend/node_modules/@babel/parser/lib/index.js:11153:21)
    at JSXParserMixin.parseMaybeUnary (/Users/deniskanukov/online_reception_of_appeals/mysite/frontend/node_modules/@babel/parser/lib/index.js:11127:23)
    at JSXParserMixin.parseMaybeUnaryOrPrivate (/Users/deniskanukov/online_reception_of_appeals/mysite/frontend/node_modules/@babel/parser/lib/index.js:10956:61)
    at JSXParserMixin.parseExprOps (/Users/deniskanukov/online_reception_of_appeals/mysite/frontend/node_modules/@babel/parser/lib/index.js:10962:23)
    at JSXParserMixin.parseMaybeConditional (/Users/deniskanukov/online_reception_of_appeals/mysite/frontend/node_modules/@babel/parser/lib/index.js:10937:23)
    at JSXParserMixin.parseMaybeAssign (/Users/deniskanukov/online_reception_of_appeals/mysite/frontend/node_modules/@babel/parser/lib/index.js:10895:21)
    at /Users/deniskanukov/online_reception_of_appeals/mysite/frontend/node_modules/@babel/parser/lib/index.js:10863:39
    at JSXParserMixin.allowInAnd (/Users/deniskanukov/online_reception_of_appeals/mysite/frontend/node_modules/@babel/parser/lib/index.js:12640:12)
    at JSXParserMixin.parseMaybeAssignAllowIn (/Users/deniskanukov/online_reception_of_appeals/mysite/frontend/node_modules/@babel/parser/lib/index.js:10863:17)
    at JSXParserMixin.parseExprListItem (/Users/deniskanukov/online_reception_of_appeals/mysite/frontend/node_modules/@babel/parser/lib/index.js:12380:18)
    at JSXParserMixin.parseCallExpressionArguments (/Users/deniskanukov/online_reception_of_appeals/mysite/frontend/node_modules/@babel/parser/lib/index.js:11367:22)
    at JSXParserMixin.parseCoverCallAndAsyncArrowHead (/Users/deniskanukov/online_reception_of_appeals/mysite/frontend/node_modules/@babel/parser/lib/index.js:11279:29)
    at JSXParserMixin.parseSubscript (/Users/deniskanukov/online_reception_of_appeals/mysite/frontend/node_modules/@babel/parser/lib/index.js:11210:19)
    at JSXParserMixin.parseSubscripts (/Users/deniskanukov/online_reception_of_appeals/mysite/frontend/node_modules/@babel/parser/lib/index.js:11184:19)
    at JSXParserMixin.parseExprSubscripts (/Users/deniskanukov/online_reception_of_appeals/mysite/frontend/node_modules/@babel/parser/lib/index.js:11175:17)
    at JSXParserMixin.parseUpdate (/Users/deniskanukov/online_reception_of_appeals/mysite/frontend/node_modules/@babel/parser/lib/index.js:11153:21)
    at JSXParserMixin.parseMaybeUnary (/Users/deniskanukov/online_reception_of_appeals/mysite/frontend/node_modules/@babel/parser/lib/index.js:11127:23)
    at JSXParserMixin.parseMaybeUnaryOrPrivate (/Users/deniskanukov/online_reception_of_appeals/mysite/frontend/node_modules/@babel/parser/lib/index.js:10956:61)
    at JSXParserMixin.parseExprOps (/Users/deniskanukov/online_reception_of_appeals/mysite/frontend/node_modules/@babel/parser/lib/index.js:10962:23)
    at JSXParserMixin.parseMaybeConditional (/Users/deniskanukov/online_reception_of_appeals/mysite/frontend/node_modules/@babel/parser/lib/index.js:10937:23)
    at JSXParserMixin.parseMaybeAssign (/Users/deniskanukov/online_reception_of_appeals/mysite/frontend/node_modules/@babel/parser/lib/index.js:10895:21)
    at /Users/deniskanukov/online_reception_of_appeals/mysite/frontend/node_modules/@babel/parser/lib/index.js:10863:39
    at JSXParserMixin.allowInAnd (/Users/deniskanukov/online_reception_of_appeals/mysite/frontend/node_modules/@babel/parser/lib/index.js:12640:12)
    at JSXParserMixin.parseMaybeAssignAllowIn (/Users/deniskanukov/online_reception_of_appeals/mysite/frontend/node_modules/@babel/parser/lib/index.js:10863:17)
    at JSXParserMixin.parseObjectProperty (/Users/deniskanukov/online_reception_of_appeals/mysite/frontend/node_modules/@babel/parser/lib/index.js:12127:83)
    at JSXParserMixin.parseObjPropValue (/Users/deniskanukov/online_reception_of_appeals/mysite/frontend/node_modules/@babel/parser/lib/index.js:12154:100)
    at JSXParserMixin.parsePropertyDefinition (/Users/deniskanukov/online_reception_of_appeals/mysite/frontend/node_modules/@babel/parser/lib/index.js:12083:17)
    at JSXParserMixin.parseObjectLike (/Users/deniskanukov/online_reception_of_appeals/mysite/frontend/node_modules/@babel/parser/lib/index.js:11993:21)
            
2023-01-05 14:48:07,703 ERROR "GET /appeal/ HTTP/1.1" 500 171643
2023-01-05 14:48:08,668 ERROR Internal Server Error: /appeal/
Traceback (most recent call last):
  File "/Library/Frameworks/Python.framework/Versions/3.10/lib/python3.10/site-packages/django/core/handlers/exception.py", line 55, in inner
    response = get_response(request)
  File "/Library/Frameworks/Python.framework/Versions/3.10/lib/python3.10/site-packages/django/core/handlers/base.py", line 220, in _get_response
    response = response.render()
  File "/Library/Frameworks/Python.framework/Versions/3.10/lib/python3.10/site-packages/django/template/response.py", line 114, in render
    self.content = self.rendered_content
  File "/Library/Frameworks/Python.framework/Versions/3.10/lib/python3.10/site-packages/django/template/response.py", line 92, in rendered_content
    return template.render(context, self._request)
  File "/Library/Frameworks/Python.framework/Versions/3.10/lib/python3.10/site-packages/django/template/backends/django.py", line 62, in render
    return self.template.render(context)
  File "/Library/Frameworks/Python.framework/Versions/3.10/lib/python3.10/site-packages/django/template/base.py", line 175, in render
    return self._render(context)
  File "/Library/Frameworks/Python.framework/Versions/3.10/lib/python3.10/site-packages/django/template/base.py", line 167, in _render
    return self.nodelist.render(context)
  File "/Library/Frameworks/Python.framework/Versions/3.10/lib/python3.10/site-packages/django/template/base.py", line 1000, in render
    return SafeString("".join([node.render_annotated(context) for node in self]))
  File "/Library/Frameworks/Python.framework/Versions/3.10/lib/python3.10/site-packages/django/template/base.py", line 1000, in <listcomp>
    return SafeString("".join([node.render_annotated(context) for node in self]))
  File "/Library/Frameworks/Python.framework/Versions/3.10/lib/python3.10/site-packages/django/template/base.py", line 958, in render_annotated
    return self.render(context)
  File "/Library/Frameworks/Python.framework/Versions/3.10/lib/python3.10/site-packages/django/template/library.py", line 239, in render
    output = self.func(*resolved_args, **resolved_kwargs)
  File "/Library/Frameworks/Python.framework/Versions/3.10/lib/python3.10/site-packages/webpack_loader/templatetags/webpack_loader.py", line 12, in render_bundle
    tags = utils.get_as_tags(bundle_name, extension=extension, config=config, attrs=attrs)
  File "/Library/Frameworks/Python.framework/Versions/3.10/lib/python3.10/site-packages/webpack_loader/utils.py", line 62, in get_as_tags
    bundle = _get_bundle(bundle_name, extension, config)
  File "/Library/Frameworks/Python.framework/Versions/3.10/lib/python3.10/site-packages/webpack_loader/utils.py", line 40, in _get_bundle
    bundle = get_loader(config).get_bundle(bundle_name)
  File "/Library/Frameworks/Python.framework/Versions/3.10/lib/python3.10/site-packages/webpack_loader/loader.py", line 96, in get_bundle
    raise WebpackError(error)
webpack_loader.exceptions.WebpackError: 
            ModuleBuildError in 
            Module build failed (from ./node_modules/babel-loader/lib/index.js):
SyntaxError: /Users/deniskanukov/online_reception_of_appeals/mysite/frontend/src/components/DragndropTable.vue: Unexpected token (14:61)

  12 |   data() {
  13 |     return {
> 14 |       newTicketsProp: this.tickets.filter((ticket) => ticket.),
     |                                                              ^
  15 |       inProgressTickets: [],
  16 |       closedTickets: [],
  17 |     }
    at instantiate (/Users/deniskanukov/online_reception_of_appeals/mysite/frontend/node_modules/@babel/parser/lib/index.js:67:32)
    at constructor (/Users/deniskanukov/online_reception_of_appeals/mysite/frontend/node_modules/@babel/parser/lib/index.js:364:12)
    at JSXParserMixin.raise (/Users/deniskanukov/online_reception_of_appeals/mysite/frontend/node_modules/@babel/parser/lib/index.js:3364:19)
    at JSXParserMixin.unexpected (/Users/deniskanukov/online_reception_of_appeals/mysite/frontend/node_modules/@babel/parser/lib/index.js:3397:16)
    at JSXParserMixin.parseIdentifierName (/Users/deniskanukov/online_reception_of_appeals/mysite/frontend/node_modules/@babel/parser/lib/index.js:12404:18)
    at JSXParserMixin.parseIdentifier (/Users/deniskanukov/online_reception_of_appeals/mysite/frontend/node_modules/@babel/parser/lib/index.js:12387:23)
    at JSXParserMixin.parseMember (/Users/deniskanukov/online_reception_of_appeals/mysite/frontend/node_modules/@babel/parser/lib/index.js:11238:28)
    at JSXParserMixin.parseSubscript (/Users/deniskanukov/online_reception_of_appeals/mysite/frontend/node_modules/@babel/parser/lib/index.js:11214:21)
    at JSXParserMixin.parseSubscripts (/Users/deniskanukov/online_reception_of_appeals/mysite/frontend/node_modules/@babel/parser/lib/index.js:11184:19)
    at JSXParserMixin.parseExprSubscripts (/Users/deniskanukov/online_reception_of_appeals/mysite/frontend/node_modules/@babel/parser/lib/index.js:11175:17)
    at JSXParserMixin.parseUpdate (/Users/deniskanukov/online_reception_of_appeals/mysite/frontend/node_modules/@babel/parser/lib/index.js:11153:21)
    at JSXParserMixin.parseMaybeUnary (/Users/deniskanukov/online_reception_of_appeals/mysite/frontend/node_modules/@babel/parser/lib/index.js:11127:23)
    at JSXParserMixin.parseMaybeUnaryOrPrivate (/Users/deniskanukov/online_reception_of_appeals/mysite/frontend/node_modules/@babel/parser/lib/index.js:10956:61)
    at JSXParserMixin.parseExprOps (/Users/deniskanukov/online_reception_of_appeals/mysite/frontend/node_modules/@babel/parser/lib/index.js:10962:23)
    at JSXParserMixin.parseMaybeConditional (/Users/deniskanukov/online_reception_of_appeals/mysite/frontend/node_modules/@babel/parser/lib/index.js:10937:23)
    at JSXParserMixin.parseMaybeAssign (/Users/deniskanukov/online_reception_of_appeals/mysite/frontend/node_modules/@babel/parser/lib/index.js:10895:21)
    at JSXParserMixin.parseFunctionBody (/Users/deniskanukov/online_reception_of_appeals/mysite/frontend/node_modules/@babel/parser/lib/index.js:12279:24)
    at JSXParserMixin.parseArrowExpression (/Users/deniskanukov/online_reception_of_appeals/mysite/frontend/node_modules/@babel/parser/lib/index.js:12260:10)
    at JSXParserMixin.parseParenAndDistinguishExpression (/Users/deniskanukov/online_reception_of_appeals/mysite/frontend/node_modules/@babel/parser/lib/index.js:11829:12)
    at JSXParserMixin.parseExprAtom (/Users/deniskanukov/online_reception_of_appeals/mysite/frontend/node_modules/@babel/parser/lib/index.js:11446:23)
    at JSXParserMixin.parseExprAtom (/Users/deniskanukov/online_reception_of_appeals/mysite/frontend/node_modules/@babel/parser/lib/index.js:7238:20)
    at JSXParserMixin.parseExprSubscripts (/Users/deniskanukov/online_reception_of_appeals/mysite/frontend/node_modules/@babel/parser/lib/index.js:11171:23)
    at JSXParserMixin.parseUpdate (/Users/deniskanukov/online_reception_of_appeals/mysite/frontend/node_modules/@babel/parser/lib/index.js:11153:21)
    at JSXParserMixin.parseMaybeUnary (/Users/deniskanukov/online_reception_of_appeals/mysite/frontend/node_modules/@babel/parser/lib/index.js:11127:23)
    at JSXParserMixin.parseMaybeUnaryOrPrivate (/Users/deniskanukov/online_reception_of_appeals/mysite/frontend/node_modules/@babel/parser/lib/index.js:10956:61)
    at JSXParserMixin.parseExprOps (/Users/deniskanukov/online_reception_of_appeals/mysite/frontend/node_modules/@babel/parser/lib/index.js:10962:23)
    at JSXParserMixin.parseMaybeConditional (/Users/deniskanukov/online_reception_of_appeals/mysite/frontend/node_modules/@babel/parser/lib/index.js:10937:23)
    at JSXParserMixin.parseMaybeAssign (/Users/deniskanukov/online_reception_of_appeals/mysite/frontend/node_modules/@babel/parser/lib/index.js:10895:21)
    at /Users/deniskanukov/online_reception_of_appeals/mysite/frontend/node_modules/@babel/parser/lib/index.js:10863:39
    at JSXParserMixin.allowInAnd (/Users/deniskanukov/online_reception_of_appeals/mysite/frontend/node_modules/@babel/parser/lib/index.js:12640:12)
    at JSXParserMixin.parseMaybeAssignAllowIn (/Users/deniskanukov/online_reception_of_appeals/mysite/frontend/node_modules/@babel/parser/lib/index.js:10863:17)
    at JSXParserMixin.parseExprListItem (/Users/deniskanukov/online_reception_of_appeals/mysite/frontend/node_modules/@babel/parser/lib/index.js:12380:18)
    at JSXParserMixin.parseCallExpressionArguments (/Users/deniskanukov/online_reception_of_appeals/mysite/frontend/node_modules/@babel/parser/lib/index.js:11367:22)
    at JSXParserMixin.parseCoverCallAndAsyncArrowHead (/Users/deniskanukov/online_reception_of_appeals/mysite/frontend/node_modules/@babel/parser/lib/index.js:11279:29)
    at JSXParserMixin.parseSubscript (/Users/deniskanukov/online_reception_of_appeals/mysite/frontend/node_modules/@babel/parser/lib/index.js:11210:19)
    at JSXParserMixin.parseSubscripts (/Users/deniskanukov/online_reception_of_appeals/mysite/frontend/node_modules/@babel/parser/lib/index.js:11184:19)
    at JSXParserMixin.parseExprSubscripts (/Users/deniskanukov/online_reception_of_appeals/mysite/frontend/node_modules/@babel/parser/lib/index.js:11175:17)
    at JSXParserMixin.parseUpdate (/Users/deniskanukov/online_reception_of_appeals/mysite/frontend/node_modules/@babel/parser/lib/index.js:11153:21)
    at JSXParserMixin.parseMaybeUnary (/Users/deniskanukov/online_reception_of_appeals/mysite/frontend/node_modules/@babel/parser/lib/index.js:11127:23)
    at JSXParserMixin.parseMaybeUnaryOrPrivate (/Users/deniskanukov/online_reception_of_appeals/mysite/frontend/node_modules/@babel/parser/lib/index.js:10956:61)
    at JSXParserMixin.parseExprOps (/Users/deniskanukov/online_reception_of_appeals/mysite/frontend/node_modules/@babel/parser/lib/index.js:10962:23)
    at JSXParserMixin.parseMaybeConditional (/Users/deniskanukov/online_reception_of_appeals/mysite/frontend/node_modules/@babel/parser/lib/index.js:10937:23)
    at JSXParserMixin.parseMaybeAssign (/Users/deniskanukov/online_reception_of_appeals/mysite/frontend/node_modules/@babel/parser/lib/index.js:10895:21)
    at /Users/deniskanukov/online_reception_of_appeals/mysite/frontend/node_modules/@babel/parser/lib/index.js:10863:39
    at JSXParserMixin.allowInAnd (/Users/deniskanukov/online_reception_of_appeals/mysite/frontend/node_modules/@babel/parser/lib/index.js:12640:12)
    at JSXParserMixin.parseMaybeAssignAllowIn (/Users/deniskanukov/online_reception_of_appeals/mysite/frontend/node_modules/@babel/parser/lib/index.js:10863:17)
    at JSXParserMixin.parseObjectProperty (/Users/deniskanukov/online_reception_of_appeals/mysite/frontend/node_modules/@babel/parser/lib/index.js:12127:83)
    at JSXParserMixin.parseObjPropValue (/Users/deniskanukov/online_reception_of_appeals/mysite/frontend/node_modules/@babel/parser/lib/index.js:12154:100)
    at JSXParserMixin.parsePropertyDefinition (/Users/deniskanukov/online_reception_of_appeals/mysite/frontend/node_modules/@babel/parser/lib/index.js:12083:17)
    at JSXParserMixin.parseObjectLike (/Users/deniskanukov/online_reception_of_appeals/mysite/frontend/node_modules/@babel/parser/lib/index.js:11993:21)
            
2023-01-05 14:48:08,750 ERROR "GET /appeal/ HTTP/1.1" 500 171644
2023-01-05 14:48:27,518 WARNING Not Found: /appeal/<%= BASE_URL %>favicon.ico
2023-01-05 14:48:27,522 WARNING "GET /appeal/%3C%=%20BASE_URL%20%%3Efavicon.ico HTTP/1.1" 404 5872
2023-01-05 14:49:42,466 WARNING Not Found: /appeal/<%= BASE_URL %>favicon.ico
2023-01-05 14:49:42,467 WARNING "GET /appeal/%3C%=%20BASE_URL%20%%3Efavicon.ico HTTP/1.1" 404 5872
2023-01-05 14:50:11,513 WARNING Not Found: /appeal/<%= BASE_URL %>favicon.ico
2023-01-05 14:50:11,515 WARNING "GET /appeal/%3C%=%20BASE_URL%20%%3Efavicon.ico HTTP/1.1" 404 5872
2023-01-05 14:59:40,111 WARNING Not Found: /appeal/<%= BASE_URL %>favicon.ico
2023-01-05 14:59:40,113 WARNING "GET /appeal/%3C%=%20BASE_URL%20%%3Efavicon.ico HTTP/1.1" 404 5872
2023-01-05 15:00:12,917 WARNING Not Found: /appeal/<%= BASE_URL %>favicon.ico
2023-01-05 15:00:12,918 WARNING "GET /appeal/%3C%=%20BASE_URL%20%%3Efavicon.ico HTTP/1.1" 404 5872
2023-01-05 15:01:08,634 WARNING Not Found: /appeal/<%= BASE_URL %>favicon.ico
2023-01-05 15:01:08,635 WARNING "GET /appeal/%3C%=%20BASE_URL%20%%3Efavicon.ico HTTP/1.1" 404 5872
2023-01-05 15:02:36,873 WARNING Not Found: /appeal/<%= BASE_URL %>favicon.ico
2023-01-05 15:02:36,875 WARNING "GET /appeal/%3C%=%20BASE_URL%20%%3Efavicon.ico HTTP/1.1" 404 5872
2023-01-05 15:03:47,013 WARNING Not Found: /appeal/<%= BASE_URL %>favicon.ico
2023-01-05 15:03:47,015 WARNING "GET /appeal/%3C%=%20BASE_URL%20%%3Efavicon.ico HTTP/1.1" 404 5872
2023-01-05 15:03:52,838 WARNING Not Found: /appeal/<%= BASE_URL %>favicon.ico
2023-01-05 15:03:52,839 WARNING "GET /appeal/%3C%=%20BASE_URL%20%%3Efavicon.ico HTTP/1.1" 404 5872
2023-01-05 15:13:21,212 WARNING Not Found: /appeal/<%= BASE_URL %>favicon.ico
2023-01-05 15:13:21,214 WARNING "GET /appeal/%3C%=%20BASE_URL%20%%3Efavicon.ico HTTP/1.1" 404 5872
2023-01-05 15:20:50,297 WARNING Not Found: /appeal/<%= BASE_URL %>favicon.ico
2023-01-05 15:20:50,299 WARNING "GET /appeal/%3C%=%20BASE_URL%20%%3Efavicon.ico HTTP/1.1" 404 5872
2023-01-05 15:21:01,836 WARNING Not Found: /appeal/<%= BASE_URL %>favicon.ico
2023-01-05 15:21:01,838 WARNING "GET /appeal/%3C%=%20BASE_URL%20%%3Efavicon.ico HTTP/1.1" 404 5872
2023-01-05 15:23:05,611 ERROR Internal Server Error: /appeal/
Traceback (most recent call last):
  File "/Library/Frameworks/Python.framework/Versions/3.10/lib/python3.10/site-packages/django/core/handlers/exception.py", line 55, in inner
    response = get_response(request)
  File "/Library/Frameworks/Python.framework/Versions/3.10/lib/python3.10/site-packages/django/core/handlers/base.py", line 220, in _get_response
    response = response.render()
  File "/Library/Frameworks/Python.framework/Versions/3.10/lib/python3.10/site-packages/django/template/response.py", line 114, in render
    self.content = self.rendered_content
  File "/Library/Frameworks/Python.framework/Versions/3.10/lib/python3.10/site-packages/django/template/response.py", line 92, in rendered_content
    return template.render(context, self._request)
  File "/Library/Frameworks/Python.framework/Versions/3.10/lib/python3.10/site-packages/django/template/backends/django.py", line 62, in render
    return self.template.render(context)
  File "/Library/Frameworks/Python.framework/Versions/3.10/lib/python3.10/site-packages/django/template/base.py", line 175, in render
    return self._render(context)
  File "/Library/Frameworks/Python.framework/Versions/3.10/lib/python3.10/site-packages/django/template/base.py", line 167, in _render
    return self.nodelist.render(context)
  File "/Library/Frameworks/Python.framework/Versions/3.10/lib/python3.10/site-packages/django/template/base.py", line 1000, in render
    return SafeString("".join([node.render_annotated(context) for node in self]))
  File "/Library/Frameworks/Python.framework/Versions/3.10/lib/python3.10/site-packages/django/template/base.py", line 1000, in <listcomp>
    return SafeString("".join([node.render_annotated(context) for node in self]))
  File "/Library/Frameworks/Python.framework/Versions/3.10/lib/python3.10/site-packages/django/template/base.py", line 958, in render_annotated
    return self.render(context)
  File "/Library/Frameworks/Python.framework/Versions/3.10/lib/python3.10/site-packages/django/template/library.py", line 239, in render
    output = self.func(*resolved_args, **resolved_kwargs)
  File "/Library/Frameworks/Python.framework/Versions/3.10/lib/python3.10/site-packages/webpack_loader/templatetags/webpack_loader.py", line 12, in render_bundle
    tags = utils.get_as_tags(bundle_name, extension=extension, config=config, attrs=attrs)
  File "/Library/Frameworks/Python.framework/Versions/3.10/lib/python3.10/site-packages/webpack_loader/utils.py", line 62, in get_as_tags
    bundle = _get_bundle(bundle_name, extension, config)
  File "/Library/Frameworks/Python.framework/Versions/3.10/lib/python3.10/site-packages/webpack_loader/utils.py", line 40, in _get_bundle
    bundle = get_loader(config).get_bundle(bundle_name)
  File "/Library/Frameworks/Python.framework/Versions/3.10/lib/python3.10/site-packages/webpack_loader/loader.py", line 96, in get_bundle
    raise WebpackError(error)
webpack_loader.exceptions.WebpackError: 
            ESLintError in 
            [eslint] 
/Users/deniskanukov/online_reception_of_appeals/mysite/frontend/src/components/DragndropTableColumn.vue
  23:7  error  'STATUS_TUPLE' is assigned a value but never used  no-unused-vars

âœ– 1 problem (1 error, 0 warnings)

            
2023-01-05 15:23:05,760 ERROR "GET /appeal/ HTTP/1.1" 500 121312
2023-01-05 15:23:13,371 ERROR Internal Server Error: /appeal/
Traceback (most recent call last):
  File "/Library/Frameworks/Python.framework/Versions/3.10/lib/python3.10/site-packages/django/core/handlers/exception.py", line 55, in inner
    response = get_response(request)
  File "/Library/Frameworks/Python.framework/Versions/3.10/lib/python3.10/site-packages/django/core/handlers/base.py", line 220, in _get_response
    response = response.render()
  File "/Library/Frameworks/Python.framework/Versions/3.10/lib/python3.10/site-packages/django/template/response.py", line 114, in render
    self.content = self.rendered_content
  File "/Library/Frameworks/Python.framework/Versions/3.10/lib/python3.10/site-packages/django/template/response.py", line 92, in rendered_content
    return template.render(context, self._request)
  File "/Library/Frameworks/Python.framework/Versions/3.10/lib/python3.10/site-packages/django/template/backends/django.py", line 62, in render
    return self.template.render(context)
  File "/Library/Frameworks/Python.framework/Versions/3.10/lib/python3.10/site-packages/django/template/base.py", line 175, in render
    return self._render(context)
  File "/Library/Frameworks/Python.framework/Versions/3.10/lib/python3.10/site-packages/django/template/base.py", line 167, in _render
    return self.nodelist.render(context)
  File "/Library/Frameworks/Python.framework/Versions/3.10/lib/python3.10/site-packages/django/template/base.py", line 1000, in render
    return SafeString("".join([node.render_annotated(context) for node in self]))
  File "/Library/Frameworks/Python.framework/Versions/3.10/lib/python3.10/site-packages/django/template/base.py", line 1000, in <listcomp>
    return SafeString("".join([node.render_annotated(context) for node in self]))
  File "/Library/Frameworks/Python.framework/Versions/3.10/lib/python3.10/site-packages/django/template/base.py", line 958, in render_annotated
    return self.render(context)
  File "/Library/Frameworks/Python.framework/Versions/3.10/lib/python3.10/site-packages/django/template/library.py", line 239, in render
    output = self.func(*resolved_args, **resolved_kwargs)
  File "/Library/Frameworks/Python.framework/Versions/3.10/lib/python3.10/site-packages/webpack_loader/templatetags/webpack_loader.py", line 12, in render_bundle
    tags = utils.get_as_tags(bundle_name, extension=extension, config=config, attrs=attrs)
  File "/Library/Frameworks/Python.framework/Versions/3.10/lib/python3.10/site-packages/webpack_loader/utils.py", line 62, in get_as_tags
    bundle = _get_bundle(bundle_name, extension, config)
  File "/Library/Frameworks/Python.framework/Versions/3.10/lib/python3.10/site-packages/webpack_loader/utils.py", line 40, in _get_bundle
    bundle = get_loader(config).get_bundle(bundle_name)
  File "/Library/Frameworks/Python.framework/Versions/3.10/lib/python3.10/site-packages/webpack_loader/loader.py", line 96, in get_bundle
    raise WebpackError(error)
webpack_loader.exceptions.WebpackError: 
            ESLintError in 
            [eslint] 
/Users/deniskanukov/online_reception_of_appeals/mysite/frontend/src/components/DragndropTableColumn.vue
  23:7  error  'STATUS_TUPLE' is assigned a value but never used  no-unused-vars

âœ– 1 problem (1 error, 0 warnings)

            
2023-01-05 15:23:13,395 ERROR "GET /appeal/ HTTP/1.1" 500 121312
2023-01-05 15:23:14,935 WARNING Not Found: /appeal/<%= BASE_URL %>favicon.ico
2023-01-05 15:23:14,936 WARNING "GET /appeal/%3C%=%20BASE_URL%20%%3Efavicon.ico HTTP/1.1" 404 5872
2023-01-05 15:29:16,343 ERROR Internal Server Error: /appeal/
Traceback (most recent call last):
  File "/Library/Frameworks/Python.framework/Versions/3.10/lib/python3.10/site-packages/django/core/handlers/exception.py", line 55, in inner
    response = get_response(request)
  File "/Library/Frameworks/Python.framework/Versions/3.10/lib/python3.10/site-packages/django/core/handlers/base.py", line 220, in _get_response
    response = response.render()
  File "/Library/Frameworks/Python.framework/Versions/3.10/lib/python3.10/site-packages/django/template/response.py", line 114, in render
    self.content = self.rendered_content
  File "/Library/Frameworks/Python.framework/Versions/3.10/lib/python3.10/site-packages/django/template/response.py", line 92, in rendered_content
    return template.render(context, self._request)
  File "/Library/Frameworks/Python.framework/Versions/3.10/lib/python3.10/site-packages/django/template/backends/django.py", line 62, in render
    return self.template.render(context)
  File "/Library/Frameworks/Python.framework/Versions/3.10/lib/python3.10/site-packages/django/template/base.py", line 175, in render
    return self._render(context)
  File "/Library/Frameworks/Python.framework/Versions/3.10/lib/python3.10/site-packages/django/template/base.py", line 167, in _render
    return self.nodelist.render(context)
  File "/Library/Frameworks/Python.framework/Versions/3.10/lib/python3.10/site-packages/django/template/base.py", line 1000, in render
    return SafeString("".join([node.render_annotated(context) for node in self]))
  File "/Library/Frameworks/Python.framework/Versions/3.10/lib/python3.10/site-packages/django/template/base.py", line 1000, in <listcomp>
    return SafeString("".join([node.render_annotated(context) for node in self]))
  File "/Library/Frameworks/Python.framework/Versions/3.10/lib/python3.10/site-packages/django/template/base.py", line 958, in render_annotated
    return self.render(context)
  File "/Library/Frameworks/Python.framework/Versions/3.10/lib/python3.10/site-packages/django/template/library.py", line 239, in render
    output = self.func(*resolved_args, **resolved_kwargs)
  File "/Library/Frameworks/Python.framework/Versions/3.10/lib/python3.10/site-packages/webpack_loader/templatetags/webpack_loader.py", line 12, in render_bundle
    tags = utils.get_as_tags(bundle_name, extension=extension, config=config, attrs=attrs)
  File "/Library/Frameworks/Python.framework/Versions/3.10/lib/python3.10/site-packages/webpack_loader/utils.py", line 62, in get_as_tags
    bundle = _get_bundle(bundle_name, extension, config)
  File "/Library/Frameworks/Python.framework/Versions/3.10/lib/python3.10/site-packages/webpack_loader/utils.py", line 40, in _get_bundle
    bundle = get_loader(config).get_bundle(bundle_name)
  File "/Library/Frameworks/Python.framework/Versions/3.10/lib/python3.10/site-packages/webpack_loader/loader.py", line 96, in get_bundle
    raise WebpackError(error)
webpack_loader.exceptions.WebpackError: 
            ModuleError in 
            Module Error (from ./node_modules/vue-loader/dist/templateLoader.js):

VueCompilerError: v-bind is missing expression.
at /Users/deniskanukov/online_reception_of_appeals/mysite/frontend/src/components/DragndropTable.vue:31:11
29 |            }"
30 |            :tickets="closedTickets"
31 |            :setNewTicketStatusById
   |            ^^^^^^^^^^^^^^^^^^^^^^^
32 |        />
33 |      </v-col>

            
2023-01-05 15:29:16,376 ERROR "GET /appeal/ HTTP/1.1" 500 123017
2023-01-05 15:29:17,459 ERROR Internal Server Error: /appeal/
Traceback (most recent call last):
  File "/Library/Frameworks/Python.framework/Versions/3.10/lib/python3.10/site-packages/django/core/handlers/exception.py", line 55, in inner
    response = get_response(request)
  File "/Library/Frameworks/Python.framework/Versions/3.10/lib/python3.10/site-packages/django/core/handlers/base.py", line 220, in _get_response
    response = response.render()
  File "/Library/Frameworks/Python.framework/Versions/3.10/lib/python3.10/site-packages/django/template/response.py", line 114, in render
    self.content = self.rendered_content
  File "/Library/Frameworks/Python.framework/Versions/3.10/lib/python3.10/site-packages/django/template/response.py", line 92, in rendered_content
    return template.render(context, self._request)
  File "/Library/Frameworks/Python.framework/Versions/3.10/lib/python3.10/site-packages/django/template/backends/django.py", line 62, in render
    return self.template.render(context)
  File "/Library/Frameworks/Python.framework/Versions/3.10/lib/python3.10/site-packages/django/template/base.py", line 175, in render
    return self._render(context)
  File "/Library/Frameworks/Python.framework/Versions/3.10/lib/python3.10/site-packages/django/template/base.py", line 167, in _render
    return self.nodelist.render(context)
  File "/Library/Frameworks/Python.framework/Versions/3.10/lib/python3.10/site-packages/django/template/base.py", line 1000, in render
    return SafeString("".join([node.render_annotated(context) for node in self]))
  File "/Library/Frameworks/Python.framework/Versions/3.10/lib/python3.10/site-packages/django/template/base.py", line 1000, in <listcomp>
    return SafeString("".join([node.render_annotated(context) for node in self]))
  File "/Library/Frameworks/Python.framework/Versions/3.10/lib/python3.10/site-packages/django/template/base.py", line 958, in render_annotated
    return self.render(context)
  File "/Library/Frameworks/Python.framework/Versions/3.10/lib/python3.10/site-packages/django/template/library.py", line 239, in render
    output = self.func(*resolved_args, **resolved_kwargs)
  File "/Library/Frameworks/Python.framework/Versions/3.10/lib/python3.10/site-packages/webpack_loader/templatetags/webpack_loader.py", line 12, in render_bundle
    tags = utils.get_as_tags(bundle_name, extension=extension, config=config, attrs=attrs)
  File "/Library/Frameworks/Python.framework/Versions/3.10/lib/python3.10/site-packages/webpack_loader/utils.py", line 62, in get_as_tags
    bundle = _get_bundle(bundle_name, extension, config)
  File "/Library/Frameworks/Python.framework/Versions/3.10/lib/python3.10/site-packages/webpack_loader/utils.py", line 40, in _get_bundle
    bundle = get_loader(config).get_bundle(bundle_name)
  File "/Library/Frameworks/Python.framework/Versions/3.10/lib/python3.10/site-packages/webpack_loader/loader.py", line 96, in get_bundle
    raise WebpackError(error)
webpack_loader.exceptions.WebpackError: 
            ESLintError in 
            [eslint] 
/Users/deniskanukov/online_reception_of_appeals/mysite/frontend/src/components/DragndropTable.vue
  31:11  error  'v-bind' directives require an attribute value  vue/valid-v-bind

/Users/deniskanukov/online_reception_of_appeals/mysite/frontend/src/components/DragndropTableColumn.vue
  23:7  error  'STATUS_TUPLE' is assigned a value but never used  no-unused-vars

âœ– 2 problems (2 errors, 0 warnings)

            
2023-01-05 15:29:17,510 ERROR "GET /appeal/ HTTP/1.1" 500 123013
2023-01-05 15:29:18,451 ERROR Internal Server Error: /appeal/
Traceback (most recent call last):
  File "/Library/Frameworks/Python.framework/Versions/3.10/lib/python3.10/site-packages/django/core/handlers/exception.py", line 55, in inner
    response = get_response(request)
  File "/Library/Frameworks/Python.framework/Versions/3.10/lib/python3.10/site-packages/django/core/handlers/base.py", line 220, in _get_response
    response = response.render()
  File "/Library/Frameworks/Python.framework/Versions/3.10/lib/python3.10/site-packages/django/template/response.py", line 114, in render
    self.content = self.rendered_content
  File "/Library/Frameworks/Python.framework/Versions/3.10/lib/python3.10/site-packages/django/template/response.py", line 92, in rendered_content
    return template.render(context, self._request)
  File "/Library/Frameworks/Python.framework/Versions/3.10/lib/python3.10/site-packages/django/template/backends/django.py", line 62, in render
    return self.template.render(context)
  File "/Library/Frameworks/Python.framework/Versions/3.10/lib/python3.10/site-packages/django/template/base.py", line 175, in render
    return self._render(context)
  File "/Library/Frameworks/Python.framework/Versions/3.10/lib/python3.10/site-packages/django/template/base.py", line 167, in _render
    return self.nodelist.render(context)
  File "/Library/Frameworks/Python.framework/Versions/3.10/lib/python3.10/site-packages/django/template/base.py", line 1000, in render
    return SafeString("".join([node.render_annotated(context) for node in self]))
  File "/Library/Frameworks/Python.framework/Versions/3.10/lib/python3.10/site-packages/django/template/base.py", line 1000, in <listcomp>
    return SafeString("".join([node.render_annotated(context) for node in self]))
  File "/Library/Frameworks/Python.framework/Versions/3.10/lib/python3.10/site-packages/django/template/base.py", line 958, in render_annotated
    return self.render(context)
  File "/Library/Frameworks/Python.framework/Versions/3.10/lib/python3.10/site-packages/django/template/library.py", line 239, in render
    output = self.func(*resolved_args, **resolved_kwargs)
  File "/Library/Frameworks/Python.framework/Versions/3.10/lib/python3.10/site-packages/webpack_loader/templatetags/webpack_loader.py", line 12, in render_bundle
    tags = utils.get_as_tags(bundle_name, extension=extension, config=config, attrs=attrs)
  File "/Library/Frameworks/Python.framework/Versions/3.10/lib/python3.10/site-packages/webpack_loader/utils.py", line 62, in get_as_tags
    bundle = _get_bundle(bundle_name, extension, config)
  File "/Library/Frameworks/Python.framework/Versions/3.10/lib/python3.10/site-packages/webpack_loader/utils.py", line 40, in _get_bundle
    bundle = get_loader(config).get_bundle(bundle_name)
  File "/Library/Frameworks/Python.framework/Versions/3.10/lib/python3.10/site-packages/webpack_loader/loader.py", line 96, in get_bundle
    raise WebpackError(error)
webpack_loader.exceptions.WebpackError: 
            ESLintError in 
            [eslint] 
/Users/deniskanukov/online_reception_of_appeals/mysite/frontend/src/components/DragndropTable.vue
  31:11  error  'v-bind' directives require an attribute value  vue/valid-v-bind

/Users/deniskanukov/online_reception_of_appeals/mysite/frontend/src/components/DragndropTableColumn.vue
  23:7  error  'STATUS_TUPLE' is assigned a value but never used  no-unused-vars

âœ– 2 problems (2 errors, 0 warnings)

            
2023-01-05 15:29:18,504 ERROR "GET /appeal/ HTTP/1.1" 500 123013
2023-01-05 15:29:29,494 ERROR Internal Server Error: /appeal/
Traceback (most recent call last):
  File "/Library/Frameworks/Python.framework/Versions/3.10/lib/python3.10/site-packages/django/core/handlers/exception.py", line 55, in inner
    response = get_response(request)
  File "/Library/Frameworks/Python.framework/Versions/3.10/lib/python3.10/site-packages/django/core/handlers/base.py", line 220, in _get_response
    response = response.render()
  File "/Library/Frameworks/Python.framework/Versions/3.10/lib/python3.10/site-packages/django/template/response.py", line 114, in render
    self.content = self.rendered_content
  File "/Library/Frameworks/Python.framework/Versions/3.10/lib/python3.10/site-packages/django/template/response.py", line 92, in rendered_content
    return template.render(context, self._request)
  File "/Library/Frameworks/Python.framework/Versions/3.10/lib/python3.10/site-packages/django/template/backends/django.py", line 62, in render
    return self.template.render(context)
  File "/Library/Frameworks/Python.framework/Versions/3.10/lib/python3.10/site-packages/django/template/base.py", line 175, in render
    return self._render(context)
  File "/Library/Frameworks/Python.framework/Versions/3.10/lib/python3.10/site-packages/django/template/base.py", line 167, in _render
    return self.nodelist.render(context)
  File "/Library/Frameworks/Python.framework/Versions/3.10/lib/python3.10/site-packages/django/template/base.py", line 1000, in render
    return SafeString("".join([node.render_annotated(context) for node in self]))
  File "/Library/Frameworks/Python.framework/Versions/3.10/lib/python3.10/site-packages/django/template/base.py", line 1000, in <listcomp>
    return SafeString("".join([node.render_annotated(context) for node in self]))
  File "/Library/Frameworks/Python.framework/Versions/3.10/lib/python3.10/site-packages/django/template/base.py", line 958, in render_annotated
    return self.render(context)
  File "/Library/Frameworks/Python.framework/Versions/3.10/lib/python3.10/site-packages/django/template/library.py", line 239, in render
    output = self.func(*resolved_args, **resolved_kwargs)
  File "/Library/Frameworks/Python.framework/Versions/3.10/lib/python3.10/site-packages/webpack_loader/templatetags/webpack_loader.py", line 12, in render_bundle
    tags = utils.get_as_tags(bundle_name, extension=extension, config=config, attrs=attrs)
  File "/Library/Frameworks/Python.framework/Versions/3.10/lib/python3.10/site-packages/webpack_loader/utils.py", line 62, in get_as_tags
    bundle = _get_bundle(bundle_name, extension, config)
  File "/Library/Frameworks/Python.framework/Versions/3.10/lib/python3.10/site-packages/webpack_loader/utils.py", line 40, in _get_bundle
    bundle = get_loader(config).get_bundle(bundle_name)
  File "/Library/Frameworks/Python.framework/Versions/3.10/lib/python3.10/site-packages/webpack_loader/loader.py", line 96, in get_bundle
    raise WebpackError(error)
webpack_loader.exceptions.WebpackError: 
            ESLintError in 
            [eslint] 
/Users/deniskanukov/online_reception_of_appeals/mysite/frontend/src/components/DragndropTable.vue
  31:11  error  'v-bind' directives require an attribute value  vue/valid-v-bind

/Users/deniskanukov/online_reception_of_appeals/mysite/frontend/src/components/DragndropTableColumn.vue
  23:7  error  'STATUS_TUPLE' is assigned a value but never used  no-unused-vars

âœ– 2 problems (2 errors, 0 warnings)

            
2023-01-05 15:29:29,511 ERROR "GET /appeal/ HTTP/1.1" 500 123013
2023-01-05 15:29:30,739 ERROR Internal Server Error: /appeal/
Traceback (most recent call last):
  File "/Library/Frameworks/Python.framework/Versions/3.10/lib/python3.10/site-packages/django/core/handlers/exception.py", line 55, in inner
    response = get_response(request)
  File "/Library/Frameworks/Python.framework/Versions/3.10/lib/python3.10/site-packages/django/core/handlers/base.py", line 220, in _get_response
    response = response.render()
  File "/Library/Frameworks/Python.framework/Versions/3.10/lib/python3.10/site-packages/django/template/response.py", line 114, in render
    self.content = self.rendered_content
  File "/Library/Frameworks/Python.framework/Versions/3.10/lib/python3.10/site-packages/django/template/response.py", line 92, in rendered_content
    return template.render(context, self._request)
  File "/Library/Frameworks/Python.framework/Versions/3.10/lib/python3.10/site-packages/django/template/backends/django.py", line 62, in render
    return self.template.render(context)
  File "/Library/Frameworks/Python.framework/Versions/3.10/lib/python3.10/site-packages/django/template/base.py", line 175, in render
    return self._render(context)
  File "/Library/Frameworks/Python.framework/Versions/3.10/lib/python3.10/site-packages/django/template/base.py", line 167, in _render
    return self.nodelist.render(context)
  File "/Library/Frameworks/Python.framework/Versions/3.10/lib/python3.10/site-packages/django/template/base.py", line 1000, in render
    return SafeString("".join([node.render_annotated(context) for node in self]))
  File "/Library/Frameworks/Python.framework/Versions/3.10/lib/python3.10/site-packages/django/template/base.py", line 1000, in <listcomp>
    return SafeString("".join([node.render_annotated(context) for node in self]))
  File "/Library/Frameworks/Python.framework/Versions/3.10/lib/python3.10/site-packages/django/template/base.py", line 958, in render_annotated
    return self.render(context)
  File "/Library/Frameworks/Python.framework/Versions/3.10/lib/python3.10/site-packages/django/template/library.py", line 239, in render
    output = self.func(*resolved_args, **resolved_kwargs)
  File "/Library/Frameworks/Python.framework/Versions/3.10/lib/python3.10/site-packages/webpack_loader/templatetags/webpack_loader.py", line 12, in render_bundle
    tags = utils.get_as_tags(bundle_name, extension=extension, config=config, attrs=attrs)
  File "/Library/Frameworks/Python.framework/Versions/3.10/lib/python3.10/site-packages/webpack_loader/utils.py", line 62, in get_as_tags
    bundle = _get_bundle(bundle_name, extension, config)
  File "/Library/Frameworks/Python.framework/Versions/3.10/lib/python3.10/site-packages/webpack_loader/utils.py", line 40, in _get_bundle
    bundle = get_loader(config).get_bundle(bundle_name)
  File "/Library/Frameworks/Python.framework/Versions/3.10/lib/python3.10/site-packages/webpack_loader/loader.py", line 96, in get_bundle
    raise WebpackError(error)
webpack_loader.exceptions.WebpackError: 
            ESLintError in 
            [eslint] 
/Users/deniskanukov/online_reception_of_appeals/mysite/frontend/src/components/DragndropTable.vue
  31:11  error  'v-bind' directives require an attribute value  vue/valid-v-bind

âœ– 1 problem (1 error, 0 warnings)

            
2023-01-05 15:29:30,831 ERROR "GET /appeal/ HTTP/1.1" 500 121264
2023-01-05 15:29:31,442 ERROR Internal Server Error: /appeal/
Traceback (most recent call last):
  File "/Library/Frameworks/Python.framework/Versions/3.10/lib/python3.10/site-packages/django/core/handlers/exception.py", line 55, in inner
    response = get_response(request)
  File "/Library/Frameworks/Python.framework/Versions/3.10/lib/python3.10/site-packages/django/core/handlers/base.py", line 220, in _get_response
    response = response.render()
  File "/Library/Frameworks/Python.framework/Versions/3.10/lib/python3.10/site-packages/django/template/response.py", line 114, in render
    self.content = self.rendered_content
  File "/Library/Frameworks/Python.framework/Versions/3.10/lib/python3.10/site-packages/django/template/response.py", line 92, in rendered_content
    return template.render(context, self._request)
  File "/Library/Frameworks/Python.framework/Versions/3.10/lib/python3.10/site-packages/django/template/backends/django.py", line 62, in render
    return self.template.render(context)
  File "/Library/Frameworks/Python.framework/Versions/3.10/lib/python3.10/site-packages/django/template/base.py", line 175, in render
    return self._render(context)
  File "/Library/Frameworks/Python.framework/Versions/3.10/lib/python3.10/site-packages/django/template/base.py", line 167, in _render
    return self.nodelist.render(context)
  File "/Library/Frameworks/Python.framework/Versions/3.10/lib/python3.10/site-packages/django/template/base.py", line 1000, in render
    return SafeString("".join([node.render_annotated(context) for node in self]))
  File "/Library/Frameworks/Python.framework/Versions/3.10/lib/python3.10/site-packages/django/template/base.py", line 1000, in <listcomp>
    return SafeString("".join([node.render_annotated(context) for node in self]))
  File "/Library/Frameworks/Python.framework/Versions/3.10/lib/python3.10/site-packages/django/template/base.py", line 958, in render_annotated
    return self.render(context)
  File "/Library/Frameworks/Python.framework/Versions/3.10/lib/python3.10/site-packages/django/template/library.py", line 239, in render
    output = self.func(*resolved_args, **resolved_kwargs)
  File "/Library/Frameworks/Python.framework/Versions/3.10/lib/python3.10/site-packages/webpack_loader/templatetags/webpack_loader.py", line 12, in render_bundle
    tags = utils.get_as_tags(bundle_name, extension=extension, config=config, attrs=attrs)
  File "/Library/Frameworks/Python.framework/Versions/3.10/lib/python3.10/site-packages/webpack_loader/utils.py", line 62, in get_as_tags
    bundle = _get_bundle(bundle_name, extension, config)
  File "/Library/Frameworks/Python.framework/Versions/3.10/lib/python3.10/site-packages/webpack_loader/utils.py", line 40, in _get_bundle
    bundle = get_loader(config).get_bundle(bundle_name)
  File "/Library/Frameworks/Python.framework/Versions/3.10/lib/python3.10/site-packages/webpack_loader/loader.py", line 96, in get_bundle
    raise WebpackError(error)
webpack_loader.exceptions.WebpackError: 
            ESLintError in 
            [eslint] 
/Users/deniskanukov/online_reception_of_appeals/mysite/frontend/src/components/DragndropTable.vue
  31:11  error  'v-bind' directives require an attribute value  vue/valid-v-bind

âœ– 1 problem (1 error, 0 warnings)

            
2023-01-05 15:29:31,495 ERROR "GET /appeal/ HTTP/1.1" 500 121264
2023-01-05 15:29:49,672 ERROR Internal Server Error: /appeal/
Traceback (most recent call last):
  File "/Library/Frameworks/Python.framework/Versions/3.10/lib/python3.10/site-packages/django/core/handlers/exception.py", line 55, in inner
    response = get_response(request)
  File "/Library/Frameworks/Python.framework/Versions/3.10/lib/python3.10/site-packages/django/core/handlers/base.py", line 220, in _get_response
    response = response.render()
  File "/Library/Frameworks/Python.framework/Versions/3.10/lib/python3.10/site-packages/django/template/response.py", line 114, in render
    self.content = self.rendered_content
  File "/Library/Frameworks/Python.framework/Versions/3.10/lib/python3.10/site-packages/django/template/response.py", line 92, in rendered_content
    return template.render(context, self._request)
  File "/Library/Frameworks/Python.framework/Versions/3.10/lib/python3.10/site-packages/django/template/backends/django.py", line 62, in render
    return self.template.render(context)
  File "/Library/Frameworks/Python.framework/Versions/3.10/lib/python3.10/site-packages/django/template/base.py", line 175, in render
    return self._render(context)
  File "/Library/Frameworks/Python.framework/Versions/3.10/lib/python3.10/site-packages/django/template/base.py", line 167, in _render
    return self.nodelist.render(context)
  File "/Library/Frameworks/Python.framework/Versions/3.10/lib/python3.10/site-packages/django/template/base.py", line 1000, in render
    return SafeString("".join([node.render_annotated(context) for node in self]))
  File "/Library/Frameworks/Python.framework/Versions/3.10/lib/python3.10/site-packages/django/template/base.py", line 1000, in <listcomp>
    return SafeString("".join([node.render_annotated(context) for node in self]))
  File "/Library/Frameworks/Python.framework/Versions/3.10/lib/python3.10/site-packages/django/template/base.py", line 958, in render_annotated
    return self.render(context)
  File "/Library/Frameworks/Python.framework/Versions/3.10/lib/python3.10/site-packages/django/template/library.py", line 239, in render
    output = self.func(*resolved_args, **resolved_kwargs)
  File "/Library/Frameworks/Python.framework/Versions/3.10/lib/python3.10/site-packages/webpack_loader/templatetags/webpack_loader.py", line 12, in render_bundle
    tags = utils.get_as_tags(bundle_name, extension=extension, config=config, attrs=attrs)
  File "/Library/Frameworks/Python.framework/Versions/3.10/lib/python3.10/site-packages/webpack_loader/utils.py", line 62, in get_as_tags
    bundle = _get_bundle(bundle_name, extension, config)
  File "/Library/Frameworks/Python.framework/Versions/3.10/lib/python3.10/site-packages/webpack_loader/utils.py", line 40, in _get_bundle
    bundle = get_loader(config).get_bundle(bundle_name)
  File "/Library/Frameworks/Python.framework/Versions/3.10/lib/python3.10/site-packages/webpack_loader/loader.py", line 96, in get_bundle
    raise WebpackError(error)
webpack_loader.exceptions.WebpackError: 
            ESLintError in 
            [eslint] 
/Users/deniskanukov/online_reception_of_appeals/mysite/frontend/src/components/DragndropTable.vue
  31:11  error  'v-bind' directives require an attribute value  vue/valid-v-bind

âœ– 1 problem (1 error, 0 warnings)

            
2023-01-05 15:29:49,741 ERROR "GET /appeal/ HTTP/1.1" 500 121264
2023-01-05 15:30:55,062 ERROR Internal Server Error: /appeal/
Traceback (most recent call last):
  File "/Library/Frameworks/Python.framework/Versions/3.10/lib/python3.10/site-packages/django/core/handlers/exception.py", line 55, in inner
    response = get_response(request)
  File "/Library/Frameworks/Python.framework/Versions/3.10/lib/python3.10/site-packages/django/core/handlers/base.py", line 220, in _get_response
    response = response.render()
  File "/Library/Frameworks/Python.framework/Versions/3.10/lib/python3.10/site-packages/django/template/response.py", line 114, in render
    self.content = self.rendered_content
  File "/Library/Frameworks/Python.framework/Versions/3.10/lib/python3.10/site-packages/django/template/response.py", line 92, in rendered_content
    return template.render(context, self._request)
  File "/Library/Frameworks/Python.framework/Versions/3.10/lib/python3.10/site-packages/django/template/backends/django.py", line 62, in render
    return self.template.render(context)
  File "/Library/Frameworks/Python.framework/Versions/3.10/lib/python3.10/site-packages/django/template/base.py", line 175, in render
    return self._render(context)
  File "/Library/Frameworks/Python.framework/Versions/3.10/lib/python3.10/site-packages/django/template/base.py", line 167, in _render
    return self.nodelist.render(context)
  File "/Library/Frameworks/Python.framework/Versions/3.10/lib/python3.10/site-packages/django/template/base.py", line 1000, in render
    return SafeString("".join([node.render_annotated(context) for node in self]))
  File "/Library/Frameworks/Python.framework/Versions/3.10/lib/python3.10/site-packages/django/template/base.py", line 1000, in <listcomp>
    return SafeString("".join([node.render_annotated(context) for node in self]))
  File "/Library/Frameworks/Python.framework/Versions/3.10/lib/python3.10/site-packages/django/template/base.py", line 958, in render_annotated
    return self.render(context)
  File "/Library/Frameworks/Python.framework/Versions/3.10/lib/python3.10/site-packages/django/template/library.py", line 239, in render
    output = self.func(*resolved_args, **resolved_kwargs)
  File "/Library/Frameworks/Python.framework/Versions/3.10/lib/python3.10/site-packages/webpack_loader/templatetags/webpack_loader.py", line 12, in render_bundle
    tags = utils.get_as_tags(bundle_name, extension=extension, config=config, attrs=attrs)
  File "/Library/Frameworks/Python.framework/Versions/3.10/lib/python3.10/site-packages/webpack_loader/utils.py", line 62, in get_as_tags
    bundle = _get_bundle(bundle_name, extension, config)
  File "/Library/Frameworks/Python.framework/Versions/3.10/lib/python3.10/site-packages/webpack_loader/utils.py", line 40, in _get_bundle
    bundle = get_loader(config).get_bundle(bundle_name)
  File "/Library/Frameworks/Python.framework/Versions/3.10/lib/python3.10/site-packages/webpack_loader/loader.py", line 96, in get_bundle
    raise WebpackError(error)
webpack_loader.exceptions.WebpackError: 
            ESLintError in 
            [eslint] 
/Users/deniskanukov/online_reception_of_appeals/mysite/frontend/src/components/DragndropTable.vue
  31:11  error  'v-bind' directives require an attribute value  vue/valid-v-bind

âœ– 1 problem (1 error, 0 warnings)

            
2023-01-05 15:30:55,076 ERROR "GET /appeal/ HTTP/1.1" 500 121264
2023-01-05 15:30:56,227 ERROR Internal Server Error: /appeal/
Traceback (most recent call last):
  File "/Library/Frameworks/Python.framework/Versions/3.10/lib/python3.10/site-packages/django/core/handlers/exception.py", line 55, in inner
    response = get_response(request)
  File "/Library/Frameworks/Python.framework/Versions/3.10/lib/python3.10/site-packages/django/core/handlers/base.py", line 220, in _get_response
    response = response.render()
  File "/Library/Frameworks/Python.framework/Versions/3.10/lib/python3.10/site-packages/django/template/response.py", line 114, in render
    self.content = self.rendered_content
  File "/Library/Frameworks/Python.framework/Versions/3.10/lib/python3.10/site-packages/django/template/response.py", line 92, in rendered_content
    return template.render(context, self._request)
  File "/Library/Frameworks/Python.framework/Versions/3.10/lib/python3.10/site-packages/django/template/backends/django.py", line 62, in render
    return self.template.render(context)
  File "/Library/Frameworks/Python.framework/Versions/3.10/lib/python3.10/site-packages/django/template/base.py", line 175, in render
    return self._render(context)
  File "/Library/Frameworks/Python.framework/Versions/3.10/lib/python3.10/site-packages/django/template/base.py", line 167, in _render
    return self.nodelist.render(context)
  File "/Library/Frameworks/Python.framework/Versions/3.10/lib/python3.10/site-packages/django/template/base.py", line 1000, in render
    return SafeString("".join([node.render_annotated(context) for node in self]))
  File "/Library/Frameworks/Python.framework/Versions/3.10/lib/python3.10/site-packages/django/template/base.py", line 1000, in <listcomp>
    return SafeString("".join([node.render_annotated(context) for node in self]))
  File "/Library/Frameworks/Python.framework/Versions/3.10/lib/python3.10/site-packages/django/template/base.py", line 958, in render_annotated
    return self.render(context)
  File "/Library/Frameworks/Python.framework/Versions/3.10/lib/python3.10/site-packages/django/template/library.py", line 239, in render
    output = self.func(*resolved_args, **resolved_kwargs)
  File "/Library/Frameworks/Python.framework/Versions/3.10/lib/python3.10/site-packages/webpack_loader/templatetags/webpack_loader.py", line 12, in render_bundle
    tags = utils.get_as_tags(bundle_name, extension=extension, config=config, attrs=attrs)
  File "/Library/Frameworks/Python.framework/Versions/3.10/lib/python3.10/site-packages/webpack_loader/utils.py", line 62, in get_as_tags
    bundle = _get_bundle(bundle_name, extension, config)
  File "/Library/Frameworks/Python.framework/Versions/3.10/lib/python3.10/site-packages/webpack_loader/utils.py", line 40, in _get_bundle
    bundle = get_loader(config).get_bundle(bundle_name)
  File "/Library/Frameworks/Python.framework/Versions/3.10/lib/python3.10/site-packages/webpack_loader/loader.py", line 96, in get_bundle
    raise WebpackError(error)
webpack_loader.exceptions.WebpackError: 
            ModuleError in 
            Module Error (from ./node_modules/vue-loader/dist/index.js):

VueCompilerError: Attribute name cannot contain U+0022 ("), U+0027 ('), and U+003C (<).
at /Users/deniskanukov/online_reception_of_appeals/mysite/frontend/src/components/DragndropTable.vue:33:1
30 |              put: ['inProgress', 'new']
31 |            }"
32 |            :tickets="closedTickets"
   |                                     ^
33 |  <!--          :setNewTicketStatusById="this.setNewTicketStatusById"-->
34 |        />

            
2023-01-05 15:30:56,328 ERROR "GET /appeal/ HTTP/1.1" 500 124174
2023-01-05 15:30:57,204 ERROR Internal Server Error: /appeal/
Traceback (most recent call last):
  File "/Library/Frameworks/Python.framework/Versions/3.10/lib/python3.10/site-packages/django/core/handlers/exception.py", line 55, in inner
    response = get_response(request)
  File "/Library/Frameworks/Python.framework/Versions/3.10/lib/python3.10/site-packages/django/core/handlers/base.py", line 220, in _get_response
    response = response.render()
  File "/Library/Frameworks/Python.framework/Versions/3.10/lib/python3.10/site-packages/django/template/response.py", line 114, in render
    self.content = self.rendered_content
  File "/Library/Frameworks/Python.framework/Versions/3.10/lib/python3.10/site-packages/django/template/response.py", line 92, in rendered_content
    return template.render(context, self._request)
  File "/Library/Frameworks/Python.framework/Versions/3.10/lib/python3.10/site-packages/django/template/backends/django.py", line 62, in render
    return self.template.render(context)
  File "/Library/Frameworks/Python.framework/Versions/3.10/lib/python3.10/site-packages/django/template/base.py", line 175, in render
    return self._render(context)
  File "/Library/Frameworks/Python.framework/Versions/3.10/lib/python3.10/site-packages/django/template/base.py", line 167, in _render
    return self.nodelist.render(context)
  File "/Library/Frameworks/Python.framework/Versions/3.10/lib/python3.10/site-packages/django/template/base.py", line 1000, in render
    return SafeString("".join([node.render_annotated(context) for node in self]))
  File "/Library/Frameworks/Python.framework/Versions/3.10/lib/python3.10/site-packages/django/template/base.py", line 1000, in <listcomp>
    return SafeString("".join([node.render_annotated(context) for node in self]))
  File "/Library/Frameworks/Python.framework/Versions/3.10/lib/python3.10/site-packages/django/template/base.py", line 958, in render_annotated
    return self.render(context)
  File "/Library/Frameworks/Python.framework/Versions/3.10/lib/python3.10/site-packages/django/template/library.py", line 239, in render
    output = self.func(*resolved_args, **resolved_kwargs)
  File "/Library/Frameworks/Python.framework/Versions/3.10/lib/python3.10/site-packages/webpack_loader/templatetags/webpack_loader.py", line 12, in render_bundle
    tags = utils.get_as_tags(bundle_name, extension=extension, config=config, attrs=attrs)
  File "/Library/Frameworks/Python.framework/Versions/3.10/lib/python3.10/site-packages/webpack_loader/utils.py", line 62, in get_as_tags
    bundle = _get_bundle(bundle_name, extension, config)
  File "/Library/Frameworks/Python.framework/Versions/3.10/lib/python3.10/site-packages/webpack_loader/utils.py", line 40, in _get_bundle
    bundle = get_loader(config).get_bundle(bundle_name)
  File "/Library/Frameworks/Python.framework/Versions/3.10/lib/python3.10/site-packages/webpack_loader/loader.py", line 96, in get_bundle
    raise WebpackError(error)
webpack_loader.exceptions.WebpackError: 
            ModuleError in 
            Module Error (from ./node_modules/vue-loader/dist/index.js):

VueCompilerError: Attribute name cannot contain U+0022 ("), U+0027 ('), and U+003C (<).
at /Users/deniskanukov/online_reception_of_appeals/mysite/frontend/src/components/DragndropTable.vue:33:1
30 |              put: ['inProgress', 'new']
31 |            }"
32 |            :tickets="closedTickets"
   |                                     ^
33 |  <!--          :setNewTicketStatusById="this.setNewTicketStatusById"-->
34 |        />

            
2023-01-05 15:30:57,259 ERROR "GET /appeal/ HTTP/1.1" 500 124175
2023-01-05 15:31:20,151 WARNING Not Found: /appeal/<%= BASE_URL %>favicon.ico
2023-01-05 15:31:20,155 WARNING "GET /appeal/%3C%=%20BASE_URL%20%%3Efavicon.ico HTTP/1.1" 404 5872
2023-01-05 15:31:21,596 WARNING Not Found: /appeal/<%= BASE_URL %>favicon.ico
2023-01-05 15:31:21,597 WARNING "GET /appeal/%3C%=%20BASE_URL%20%%3Efavicon.ico HTTP/1.1" 404 5872
2023-01-05 15:31:38,943 WARNING Not Found: /appeal/<%= BASE_URL %>favicon.ico
2023-01-05 15:31:38,945 WARNING "GET /appeal/%3C%=%20BASE_URL%20%%3Efavicon.ico HTTP/1.1" 404 5872
2023-01-05 15:32:13,273 WARNING Not Found: /appeal/<%= BASE_URL %>favicon.ico
2023-01-05 15:32:13,275 WARNING "GET /appeal/%3C%=%20BASE_URL%20%%3Efavicon.ico HTTP/1.1" 404 5872
2023-01-05 15:32:48,683 WARNING Not Found: /appeal/<%= BASE_URL %>favicon.ico
2023-01-05 15:32:48,685 WARNING "GET /appeal/%3C%=%20BASE_URL%20%%3Efavicon.ico HTTP/1.1" 404 5872
2023-01-05 15:32:59,669 WARNING Not Found: /appeal/<%= BASE_URL %>favicon.ico
2023-01-05 15:32:59,670 WARNING "GET /appeal/%3C%=%20BASE_URL%20%%3Efavicon.ico HTTP/1.1" 404 5872
2023-01-05 15:33:01,021 WARNING Not Found: /appeal/<%= BASE_URL %>favicon.ico
2023-01-05 15:33:01,025 WARNING "GET /appeal/%3C%=%20BASE_URL%20%%3Efavicon.ico HTTP/1.1" 404 5872
2023-01-05 15:33:08,441 WARNING Not Found: /appeal/<%= BASE_URL %>favicon.ico
2023-01-05 15:33:08,442 WARNING "GET /appeal/%3C%=%20BASE_URL%20%%3Efavicon.ico HTTP/1.1" 404 5872
2023-01-05 15:33:22,157 WARNING Not Found: /appeal/<%= BASE_URL %>favicon.ico
2023-01-05 15:33:22,159 WARNING "GET /appeal/%3C%=%20BASE_URL%20%%3Efavicon.ico HTTP/1.1" 404 5872
2023-01-05 15:33:42,794 WARNING Not Found: /appeal/<%= BASE_URL %>favicon.ico
2023-01-05 15:33:42,796 WARNING "GET /appeal/%3C%=%20BASE_URL%20%%3Efavicon.ico HTTP/1.1" 404 5872
2023-01-05 15:33:58,797 WARNING Not Found: /appeal/<%= BASE_URL %>favicon.ico
2023-01-05 15:33:58,798 WARNING "GET /appeal/%3C%=%20BASE_URL%20%%3Efavicon.ico HTTP/1.1" 404 5872
2023-01-05 15:34:19,354 WARNING Not Found: /appeal/<%= BASE_URL %>favicon.ico
2023-01-05 15:34:19,356 WARNING "GET /appeal/%3C%=%20BASE_URL%20%%3Efavicon.ico HTTP/1.1" 404 5872
2023-01-05 15:34:33,648 WARNING Not Found: /appeal/<%= BASE_URL %>favicon.ico
2023-01-05 15:34:33,649 WARNING "GET /appeal/%3C%=%20BASE_URL%20%%3Efavicon.ico HTTP/1.1" 404 5872
2023-01-05 15:34:33,949 WARNING Not Found: /appeal/<%= BASE_URL %>favicon.ico
2023-01-05 15:34:33,950 WARNING "GET /appeal/%3C%=%20BASE_URL%20%%3Efavicon.ico HTTP/1.1" 404 5872
2023-01-05 15:35:57,236 WARNING Not Found: /appeal/<%= BASE_URL %>favicon.ico
2023-01-05 15:35:57,237 WARNING "GET /appeal/%3C%=%20BASE_URL%20%%3Efavicon.ico HTTP/1.1" 404 5872
2023-01-05 15:36:44,040 WARNING Not Found: /appeal/<%= BASE_URL %>favicon.ico
2023-01-05 15:36:44,042 WARNING "GET /appeal/%3C%=%20BASE_URL%20%%3Efavicon.ico HTTP/1.1" 404 5872
2023-01-05 15:36:44,360 WARNING Not Found: /appeal/<%= BASE_URL %>favicon.ico
2023-01-05 15:36:44,361 WARNING "GET /appeal/%3C%=%20BASE_URL%20%%3Efavicon.ico HTTP/1.1" 404 5872
2023-01-05 15:37:13,446 WARNING Not Found: /appeal/<%= BASE_URL %>favicon.ico
2023-01-05 15:37:13,447 WARNING "GET /appeal/%3C%=%20BASE_URL%20%%3Efavicon.ico HTTP/1.1" 404 5872
2023-01-05 15:37:22,536 WARNING Not Found: /appeal/<%= BASE_URL %>favicon.ico
2023-01-05 15:37:22,537 WARNING "GET /appeal/%3C%=%20BASE_URL%20%%3Efavicon.ico HTTP/1.1" 404 5872
2023-01-05 15:39:04,900 WARNING Not Found: /appeal/<%= BASE_URL %>favicon.ico
2023-01-05 15:39:04,901 WARNING "GET /appeal/%3C%=%20BASE_URL%20%%3Efavicon.ico HTTP/1.1" 404 5872
2023-01-05 15:39:22,992 WARNING Not Found: /appeal/<%= BASE_URL %>favicon.ico
2023-01-05 15:39:22,993 WARNING "GET /appeal/%3C%=%20BASE_URL%20%%3Efavicon.ico HTTP/1.1" 404 5872
2023-01-05 15:43:15,439 WARNING Not Found: /appeal/<%= BASE_URL %>favicon.ico
2023-01-05 15:43:15,440 WARNING "GET /appeal/%3C%=%20BASE_URL%20%%3Efavicon.ico HTTP/1.1" 404 5872
2023-01-05 15:43:15,795 WARNING Not Found: /appeal/<%= BASE_URL %>favicon.ico
2023-01-05 15:43:15,797 WARNING "GET /appeal/%3C%=%20BASE_URL%20%%3Efavicon.ico HTTP/1.1" 404 5872
2023-01-05 15:43:27,230 WARNING Not Found: /appeal/<%= BASE_URL %>favicon.ico
2023-01-05 15:43:27,231 WARNING "GET /appeal/%3C%=%20BASE_URL%20%%3Efavicon.ico HTTP/1.1" 404 5872
2023-01-05 15:43:46,160 WARNING Not Found: /appeal/<%= BASE_URL %>favicon.ico
2023-01-05 15:43:46,161 WARNING "GET /appeal/%3C%=%20BASE_URL%20%%3Efavicon.ico HTTP/1.1" 404 5872
2023-01-05 15:43:46,575 WARNING Not Found: /appeal/<%= BASE_URL %>favicon.ico
2023-01-05 15:43:46,577 WARNING "GET /appeal/%3C%=%20BASE_URL%20%%3Efavicon.ico HTTP/1.1" 404 5872
2023-01-05 15:44:22,360 WARNING Not Found: /appeal/<%= BASE_URL %>favicon.ico
2023-01-05 15:44:22,361 WARNING "GET /appeal/%3C%=%20BASE_URL%20%%3Efavicon.ico HTTP/1.1" 404 5872
2023-01-05 15:44:22,759 WARNING Not Found: /appeal/<%= BASE_URL %>favicon.ico
2023-01-05 15:44:22,761 WARNING "GET /appeal/%3C%=%20BASE_URL%20%%3Efavicon.ico HTTP/1.1" 404 5872
2023-01-05 15:45:53,001 WARNING Not Found: /appeal/<%= BASE_URL %>favicon.ico
2023-01-05 15:45:53,003 WARNING "GET /appeal/%3C%=%20BASE_URL%20%%3Efavicon.ico HTTP/1.1" 404 5872
2023-01-05 15:46:19,753 WARNING Not Found: /appeal/<%= BASE_URL %>favicon.ico
2023-01-05 15:46:19,754 WARNING "GET /appeal/%3C%=%20BASE_URL%20%%3Efavicon.ico HTTP/1.1" 404 5872
2023-01-05 15:46:23,510 WARNING Not Found: /appeal/<%= BASE_URL %>favicon.ico
2023-01-05 15:46:23,511 WARNING "GET /appeal/%3C%=%20BASE_URL%20%%3Efavicon.ico HTTP/1.1" 404 5872
2023-01-05 15:50:38,071 WARNING Not Found: /appeal/<%= BASE_URL %>favicon.ico
2023-01-05 15:50:38,072 WARNING "GET /appeal/%3C%=%20BASE_URL%20%%3Efavicon.ico HTTP/1.1" 404 5872
2023-01-05 15:52:22,858 WARNING Not Found: /appeal/<%= BASE_URL %>favicon.ico
2023-01-05 15:52:22,860 WARNING "GET /appeal/%3C%=%20BASE_URL%20%%3Efavicon.ico HTTP/1.1" 404 5872
2023-01-05 15:52:28,138 WARNING Forbidden: /api/appeal
2023-01-05 15:52:28,141 WARNING "PATCH /api/appeal HTTP/1.1" 403 45
2023-01-05 15:52:40,971 WARNING Not Found: /appeal/<%= BASE_URL %>favicon.ico
2023-01-05 15:52:40,973 WARNING "GET /appeal/%3C%=%20BASE_URL%20%%3Efavicon.ico HTTP/1.1" 404 5872
2023-01-05 15:52:44,194 WARNING Forbidden: /api/appeal
2023-01-05 15:52:44,195 WARNING "PATCH /api/appeal HTTP/1.1" 403 45
2023-01-05 15:52:50,079 WARNING Not Found: /appeal/<%= BASE_URL %>favicon.ico
2023-01-05 15:52:50,082 WARNING "GET /appeal/%3C%=%20BASE_URL%20%%3Efavicon.ico HTTP/1.1" 404 5872
2023-01-05 15:52:55,510 WARNING Forbidden: /api/appeal
2023-01-05 15:52:55,512 WARNING "PATCH /api/appeal HTTP/1.1" 403 45
2023-01-05 15:53:53,160 WARNING Not Found: /appeal/<%= BASE_URL %>favicon.ico
2023-01-05 15:53:53,163 WARNING "GET /appeal/%3C%=%20BASE_URL%20%%3Efavicon.ico HTTP/1.1" 404 5872
2023-01-05 15:53:56,878 WARNING Forbidden: /api/appeal
2023-01-05 15:53:56,881 WARNING "PATCH /api/appeal HTTP/1.1" 403 45
2023-01-05 15:53:59,298 WARNING Not Found: /appeal/<%= BASE_URL %>favicon.ico
2023-01-05 15:53:59,299 WARNING "GET /appeal/%3C%=%20BASE_URL%20%%3Efavicon.ico HTTP/1.1" 404 5872
2023-01-05 15:59:27,198 WARNING Not Found: /appeal/<%= BASE_URL %>favicon.ico
2023-01-05 15:59:27,199 WARNING "GET /appeal/%3C%=%20BASE_URL%20%%3Efavicon.ico HTTP/1.1" 404 5872
2023-01-05 15:59:33,805 WARNING Not Found: /appeal/<%= BASE_URL %>favicon.ico
2023-01-05 15:59:33,806 WARNING "GET /appeal/%3C%=%20BASE_URL%20%%3Efavicon.ico HTTP/1.1" 404 5872
2023-01-05 15:59:37,633 WARNING Forbidden: /api/appeal
2023-01-05 15:59:37,636 WARNING "PATCH /api/appeal HTTP/1.1" 403 45
2023-01-05 16:00:15,309 WARNING Not Found: /appeal/<%= BASE_URL %>favicon.ico
2023-01-05 16:00:15,310 WARNING "GET /appeal/%3C%=%20BASE_URL%20%%3Efavicon.ico HTTP/1.1" 404 5872
2023-01-05 16:00:18,141 WARNING Forbidden: /api/appeal
2023-01-05 16:00:18,143 WARNING "PATCH /api/appeal HTTP/1.1" 403 45
2023-01-05 16:00:21,928 WARNING Not Found: /appeal/<%= BASE_URL %>favicon.ico
2023-01-05 16:00:21,929 WARNING "GET /appeal/%3C%=%20BASE_URL%20%%3Efavicon.ico HTTP/1.1" 404 5872
2023-01-05 16:00:56,423 WARNING Not Found: /appeal/<%= BASE_URL %>favicon.ico
2023-01-05 16:00:56,425 WARNING "GET /appeal/%3C%=%20BASE_URL%20%%3Efavicon.ico HTTP/1.1" 404 5872
2023-01-05 16:01:13,380 WARNING Not Found: /appeal/<%= BASE_URL %>favicon.ico
2023-01-05 16:01:13,381 WARNING "GET /appeal/%3C%=%20BASE_URL%20%%3Efavicon.ico HTTP/1.1" 404 5872
2023-01-05 16:01:13,866 WARNING Not Found: /appeal/<%= BASE_URL %>favicon.ico
2023-01-05 16:01:13,867 WARNING "GET /appeal/%3C%=%20BASE_URL%20%%3Efavicon.ico HTTP/1.1" 404 5872
2023-01-05 16:01:16,109 WARNING Forbidden: /api/appeal
2023-01-05 16:01:16,112 WARNING "PATCH /api/appeal HTTP/1.1" 403 45
2023-01-05 16:01:18,551 WARNING Not Found: /appeal/<%= BASE_URL %>favicon.ico
2023-01-05 16:01:18,552 WARNING "GET /appeal/%3C%=%20BASE_URL%20%%3Efavicon.ico HTTP/1.1" 404 5872
2023-01-05 19:37:13,303 WARNING Forbidden: /api/appeal
2023-01-05 19:37:13,307 WARNING "PATCH /api/appeal HTTP/1.1" 403 45
2023-01-05 19:37:16,675 WARNING Forbidden: /api/appeal
2023-01-05 19:37:16,679 WARNING "PATCH /api/appeal HTTP/1.1" 403 45
2023-01-05 19:37:39,714 WARNING Forbidden: /api/appeal
2023-01-05 19:37:39,718 WARNING "PATCH /api/appeal HTTP/1.1" 403 45
2023-01-05 19:37:42,268 WARNING Forbidden: /api/appeal
2023-01-05 19:37:42,273 WARNING "PATCH /api/appeal HTTP/1.1" 403 45
2023-01-05 19:37:58,321 WARNING Forbidden: /api/appeal
2023-01-05 19:37:58,324 WARNING "PATCH /api/appeal HTTP/1.1" 403 45
2023-01-05 19:38:24,307 WARNING Forbidden: /api/appeal
2023-01-05 19:38:24,310 WARNING "PATCH /api/appeal HTTP/1.1" 403 45
2023-01-05 19:45:00,649 WARNING Forbidden: /api/appeal
2023-01-05 19:45:00,653 WARNING "PATCH /api/appeal HTTP/1.1" 403 45
2023-01-05 20:03:40,248 WARNING Forbidden: /api/appeal
2023-01-05 20:03:40,251 WARNING "PATCH /api/appeal HTTP/1.1" 403 45
2023-01-05 20:04:04,898 WARNING Forbidden: /api/appeal
2023-01-05 20:04:04,901 WARNING "PATCH /api/appeal HTTP/1.1" 403 45
2023-01-05 20:05:51,261 WARNING Not Found: /admin-django/
2023-01-05 20:05:51,264 WARNING "GET /admin-django/ HTTP/1.1" 404 5874
2023-01-05 20:10:26,608 WARNING Forbidden: /api/appeal
2023-01-05 20:10:26,615 WARNING "PATCH /api/appeal HTTP/1.1" 403 45
2023-01-05 20:11:18,020 WARNING Forbidden: /api/appeal
2023-01-05 20:11:18,023 WARNING "PATCH /api/appeal HTTP/1.1" 403 45
2023-01-05 20:12:35,429 WARNING Forbidden: /api/appeal
2023-01-05 20:12:35,432 WARNING "PATCH /api/appeal HTTP/1.1" 403 45
2023-01-05 20:16:14,562 WARNING Forbidden: /api/appeal
2023-01-05 20:16:14,564 WARNING "PATCH /api/appeal HTTP/1.1" 403 45
2023-01-05 20:16:23,508 WARNING Forbidden: /api/appeal
2023-01-05 20:16:23,510 WARNING "PATCH /api/appeal HTTP/1.1" 403 45
2023-01-05 20:17:24,100 WARNING Forbidden: /api/appeal
2023-01-05 20:17:24,103 WARNING "PATCH /api/appeal HTTP/1.1" 403 45
2023-01-05 23:49:42,297 WARNING Forbidden: /api/appeal
2023-01-05 23:49:42,300 WARNING "PATCH /api/appeal HTTP/1.1" 403 45
2023-01-05 23:55:12,335 WARNING Forbidden: /api/appeal
2023-01-05 23:55:12,337 WARNING "PATCH /api/appeal HTTP/1.1" 403 45
2023-01-05 23:55:44,718 WARNING Forbidden: /api/appeal
2023-01-05 23:55:44,721 WARNING "PATCH /api/appeal HTTP/1.1" 403 45
2023-01-05 23:56:10,771 ERROR Internal Server Error: /api/appeal
Traceback (most recent call last):
  File "C:\Users\HP\PycharmProjects\git_push\venv\lib\site-packages\django\core\handlers\exception.py", line 55, in inner
    response = get_response(request)
  File "C:\Users\HP\PycharmProjects\git_push\venv\lib\site-packages\django\core\handlers\base.py", line 197, in _get_response
    response = wrapped_callback(request, *callback_args, **callback_kwargs)
  File "C:\Users\HP\PycharmProjects\git_push\venv\lib\site-packages\django\views\decorators\csrf.py", line 54, in wrapped_view
    return view_func(*args, **kwargs)
  File "C:\Users\HP\PycharmProjects\git_push\venv\lib\site-packages\django\views\generic\base.py", line 84, in view
    return self.dispatch(request, *args, **kwargs)
  File "C:\Users\HP\PycharmProjects\git_push\venv\lib\site-packages\rest_framework\views.py", line 509, in dispatch
    response = self.handle_exception(exc)
  File "C:\Users\HP\PycharmProjects\git_push\venv\lib\site-packages\rest_framework\views.py", line 469, in handle_exception
    self.raise_uncaught_exception(exc)
  File "C:\Users\HP\PycharmProjects\git_push\venv\lib\site-packages\rest_framework\views.py", line 480, in raise_uncaught_exception
    raise exc
  File "C:\Users\HP\PycharmProjects\git_push\venv\lib\site-packages\rest_framework\views.py", line 506, in dispatch
    response = handler(request, *args, **kwargs)
  File "C:\Users\HP\PycharmProjects\git_push\venv\lib\site-packages\rest_framework\decorators.py", line 50, in handler
    return func(*args, **kwargs)
  File "C:\Users\HP\PycharmProjects\git_push\online_reception_of_appeals\mysite\home\views.py", line 211, in appeal_api
    print(request.user.permissions)
  File "C:\Users\HP\PycharmProjects\git_push\venv\lib\site-packages\django\utils\functional.py", line 259, in inner
    return func(self._wrapped, *args)
AttributeError: 'User' object has no attribute 'permissions'
2023-01-05 23:56:10,787 ERROR "GET /api/appeal HTTP/1.1" 500 101453
2023-01-06 00:32:03,964 WARNING Forbidden: /api/appeal
2023-01-06 00:32:03,969 WARNING "PATCH /api/appeal HTTP/1.1" 403 45
2023-01-06 00:32:14,924 WARNING Forbidden: /api/appeal
2023-01-06 00:32:14,926 WARNING "PATCH /api/appeal HTTP/1.1" 403 45
2023-01-06 00:37:46,192 ERROR Internal Server Error: /api/appeal
Traceback (most recent call last):
  File "C:\Users\HP\PycharmProjects\git_push\venv\lib\site-packages\django\core\handlers\exception.py", line 55, in inner
    response = get_response(request)
  File "C:\Users\HP\PycharmProjects\git_push\venv\lib\site-packages\django\core\handlers\base.py", line 197, in _get_response
    response = wrapped_callback(request, *callback_args, **callback_kwargs)
  File "C:\Users\HP\PycharmProjects\git_push\venv\lib\site-packages\django\views\decorators\csrf.py", line 54, in wrapped_view
    return view_func(*args, **kwargs)
  File "C:\Users\HP\PycharmProjects\git_push\venv\lib\site-packages\django\views\generic\base.py", line 84, in view
    return self.dispatch(request, *args, **kwargs)
  File "C:\Users\HP\PycharmProjects\git_push\venv\lib\site-packages\rest_framework\views.py", line 509, in dispatch
    response = self.handle_exception(exc)
  File "C:\Users\HP\PycharmProjects\git_push\venv\lib\site-packages\rest_framework\views.py", line 469, in handle_exception
    self.raise_uncaught_exception(exc)
  File "C:\Users\HP\PycharmProjects\git_push\venv\lib\site-packages\rest_framework\views.py", line 480, in raise_uncaught_exception
    raise exc
  File "C:\Users\HP\PycharmProjects\git_push\venv\lib\site-packages\rest_framework\views.py", line 506, in dispatch
    response = handler(request, *args, **kwargs)
  File "C:\Users\HP\PycharmProjects\git_push\venv\lib\site-packages\rest_framework\decorators.py", line 50, in handler
    return func(*args, **kwargs)
  File "C:\Users\HP\PycharmProjects\git_push\online_reception_of_appeals\mysite\home\views.py", line 209, in appeal_api
    request.user.chech_permissions(request)
  File "C:\Users\HP\PycharmProjects\git_push\venv\lib\site-packages\django\utils\functional.py", line 259, in inner
    return func(self._wrapped, *args)
AttributeError: 'User' object has no attribute 'chech_permissions'
2023-01-06 00:37:46,203 ERROR "GET /api/appeal HTTP/1.1" 500 101576
2023-01-06 00:37:58,690 ERROR Internal Server Error: /api/appeal
Traceback (most recent call last):
  File "C:\Users\HP\PycharmProjects\git_push\venv\lib\site-packages\django\core\handlers\exception.py", line 55, in inner
    response = get_response(request)
  File "C:\Users\HP\PycharmProjects\git_push\venv\lib\site-packages\django\core\handlers\base.py", line 197, in _get_response
    response = wrapped_callback(request, *callback_args, **callback_kwargs)
  File "C:\Users\HP\PycharmProjects\git_push\venv\lib\site-packages\django\views\decorators\csrf.py", line 54, in wrapped_view
    return view_func(*args, **kwargs)
  File "C:\Users\HP\PycharmProjects\git_push\venv\lib\site-packages\django\views\generic\base.py", line 84, in view
    return self.dispatch(request, *args, **kwargs)
  File "C:\Users\HP\PycharmProjects\git_push\venv\lib\site-packages\rest_framework\views.py", line 509, in dispatch
    response = self.handle_exception(exc)
  File "C:\Users\HP\PycharmProjects\git_push\venv\lib\site-packages\rest_framework\views.py", line 469, in handle_exception
    self.raise_uncaught_exception(exc)
  File "C:\Users\HP\PycharmProjects\git_push\venv\lib\site-packages\rest_framework\views.py", line 480, in raise_uncaught_exception
    raise exc
  File "C:\Users\HP\PycharmProjects\git_push\venv\lib\site-packages\rest_framework\views.py", line 506, in dispatch
    response = handler(request, *args, **kwargs)
  File "C:\Users\HP\PycharmProjects\git_push\venv\lib\site-packages\rest_framework\decorators.py", line 50, in handler
    return func(*args, **kwargs)
  File "C:\Users\HP\PycharmProjects\git_push\online_reception_of_appeals\mysite\home\views.py", line 209, in appeal_api
    request.user.check_permissions(request)
  File "C:\Users\HP\PycharmProjects\git_push\venv\lib\site-packages\django\utils\functional.py", line 259, in inner
    return func(self._wrapped, *args)
AttributeError: 'User' object has no attribute 'check_permissions'
2023-01-06 00:37:58,714 ERROR "GET /api/appeal HTTP/1.1" 500 101576
2023-01-06 00:39:59,569 ERROR Internal Server Error: /api/appeal
Traceback (most recent call last):
  File "C:\Users\HP\PycharmProjects\git_push\venv\lib\site-packages\django\core\handlers\exception.py", line 55, in inner
    response = get_response(request)
  File "C:\Users\HP\PycharmProjects\git_push\venv\lib\site-packages\django\core\handlers\base.py", line 197, in _get_response
    response = wrapped_callback(request, *callback_args, **callback_kwargs)
  File "C:\Users\HP\PycharmProjects\git_push\venv\lib\site-packages\django\views\decorators\csrf.py", line 54, in wrapped_view
    return view_func(*args, **kwargs)
  File "C:\Users\HP\PycharmProjects\git_push\venv\lib\site-packages\django\views\generic\base.py", line 84, in view
    return self.dispatch(request, *args, **kwargs)
  File "C:\Users\HP\PycharmProjects\git_push\venv\lib\site-packages\rest_framework\views.py", line 509, in dispatch
    response = self.handle_exception(exc)
  File "C:\Users\HP\PycharmProjects\git_push\venv\lib\site-packages\rest_framework\views.py", line 469, in handle_exception
    self.raise_uncaught_exception(exc)
  File "C:\Users\HP\PycharmProjects\git_push\venv\lib\site-packages\rest_framework\views.py", line 480, in raise_uncaught_exception
    raise exc
  File "C:\Users\HP\PycharmProjects\git_push\venv\lib\site-packages\rest_framework\views.py", line 506, in dispatch
    response = handler(request, *args, **kwargs)
  File "C:\Users\HP\PycharmProjects\git_push\venv\lib\site-packages\rest_framework\decorators.py", line 50, in handler
    return func(*args, **kwargs)
  File "C:\Users\HP\PycharmProjects\git_push\online_reception_of_appeals\mysite\home\views.py", line 211, in appeal_api
    print(request.user.is_authentificated())
  File "C:\Users\HP\PycharmProjects\git_push\venv\lib\site-packages\django\utils\functional.py", line 259, in inner
    return func(self._wrapped, *args)
AttributeError: 'User' object has no attribute 'is_authentificated'
2023-01-06 00:39:59,587 ERROR "GET /api/appeal HTTP/1.1" 500 101560
2023-01-06 00:40:52,726 ERROR Internal Server Error: /api/appeal
Traceback (most recent call last):
  File "C:\Users\HP\PycharmProjects\git_push\venv\lib\site-packages\django\core\handlers\exception.py", line 55, in inner
    response = get_response(request)
  File "C:\Users\HP\PycharmProjects\git_push\venv\lib\site-packages\django\core\handlers\base.py", line 197, in _get_response
    response = wrapped_callback(request, *callback_args, **callback_kwargs)
  File "C:\Users\HP\PycharmProjects\git_push\venv\lib\site-packages\django\views\decorators\csrf.py", line 54, in wrapped_view
    return view_func(*args, **kwargs)
  File "C:\Users\HP\PycharmProjects\git_push\venv\lib\site-packages\django\views\generic\base.py", line 84, in view
    return self.dispatch(request, *args, **kwargs)
  File "C:\Users\HP\PycharmProjects\git_push\venv\lib\site-packages\rest_framework\views.py", line 509, in dispatch
    response = self.handle_exception(exc)
  File "C:\Users\HP\PycharmProjects\git_push\venv\lib\site-packages\rest_framework\views.py", line 469, in handle_exception
    self.raise_uncaught_exception(exc)
  File "C:\Users\HP\PycharmProjects\git_push\venv\lib\site-packages\rest_framework\views.py", line 480, in raise_uncaught_exception
    raise exc
  File "C:\Users\HP\PycharmProjects\git_push\venv\lib\site-packages\rest_framework\views.py", line 506, in dispatch
    response = handler(request, *args, **kwargs)
  File "C:\Users\HP\PycharmProjects\git_push\venv\lib\site-packages\rest_framework\decorators.py", line 50, in handler
    return func(*args, **kwargs)
  File "C:\Users\HP\PycharmProjects\git_push\online_reception_of_appeals\mysite\home\views.py", line 211, in appeal_api
    print(request.user.is_authentificate())
  File "C:\Users\HP\PycharmProjects\git_push\venv\lib\site-packages\django\utils\functional.py", line 259, in inner
    return func(self._wrapped, *args)
AttributeError: 'User' object has no attribute 'is_authentificate'
2023-01-06 00:40:52,740 ERROR "GET /api/appeal HTTP/1.1" 500 101496
2023-01-06 00:42:14,608 ERROR Internal Server Error: /api/appeal
Traceback (most recent call last):
  File "C:\Users\HP\PycharmProjects\git_push\venv\lib\site-packages\django\core\handlers\exception.py", line 55, in inner
    response = get_response(request)
  File "C:\Users\HP\PycharmProjects\git_push\venv\lib\site-packages\django\core\handlers\base.py", line 197, in _get_response
    response = wrapped_callback(request, *callback_args, **callback_kwargs)
  File "C:\Users\HP\PycharmProjects\git_push\venv\lib\site-packages\django\views\decorators\csrf.py", line 54, in wrapped_view
    return view_func(*args, **kwargs)
  File "C:\Users\HP\PycharmProjects\git_push\venv\lib\site-packages\django\views\generic\base.py", line 84, in view
    return self.dispatch(request, *args, **kwargs)
  File "C:\Users\HP\PycharmProjects\git_push\venv\lib\site-packages\rest_framework\views.py", line 509, in dispatch
    response = self.handle_exception(exc)
  File "C:\Users\HP\PycharmProjects\git_push\venv\lib\site-packages\rest_framework\views.py", line 469, in handle_exception
    self.raise_uncaught_exception(exc)
  File "C:\Users\HP\PycharmProjects\git_push\venv\lib\site-packages\rest_framework\views.py", line 480, in raise_uncaught_exception
    raise exc
  File "C:\Users\HP\PycharmProjects\git_push\venv\lib\site-packages\rest_framework\views.py", line 506, in dispatch
    response = handler(request, *args, **kwargs)
  File "C:\Users\HP\PycharmProjects\git_push\venv\lib\site-packages\rest_framework\decorators.py", line 50, in handler
    return func(*args, **kwargs)
  File "C:\Users\HP\PycharmProjects\git_push\online_reception_of_appeals\mysite\home\views.py", line 211, in appeal_api
    print(request.user.is_authenticated())
TypeError: 'bool' object is not callable
2023-01-06 00:42:14,626 ERROR "GET /api/appeal HTTP/1.1" 500 97570
2023-01-06 00:43:14,744 WARNING Forbidden: /api/appeal
2023-01-06 00:43:14,746 WARNING "PATCH /api/appeal HTTP/1.1" 403 45
2023-01-06 00:43:36,021 WARNING Forbidden: /api/appeal
2023-01-06 00:43:36,024 WARNING "PATCH /api/appeal HTTP/1.1" 403 45
2023-01-06 00:53:19,870 WARNING Forbidden: /api/appeal
2023-01-06 00:53:19,873 WARNING "PATCH /api/appeal HTTP/1.1" 403 45
2023-01-06 00:54:13,087 WARNING Forbidden: /api/appeal
2023-01-06 00:54:13,090 WARNING "PATCH /api/appeal HTTP/1.1" 403 45
2023-01-06 00:55:50,087 WARNING Forbidden: /api/appeal
2023-01-06 00:55:50,091 WARNING "PATCH /api/appeal HTTP/1.1" 403 45
2023-01-06 00:56:38,965 WARNING Forbidden: /api/appeal
2023-01-06 00:56:38,969 WARNING "PATCH /api/appeal HTTP/1.1" 403 45
2023-01-06 00:59:28,240 WARNING Forbidden: /api/appeal
2023-01-06 00:59:28,245 WARNING "PATCH /api/appeal HTTP/1.1" 403 45
2023-01-06 01:03:57,538 WARNING Forbidden: /api/appeal
2023-01-06 01:03:57,541 WARNING "PATCH /api/appeal HTTP/1.1" 403 45
2023-01-06 01:04:48,009 WARNING Method Not Allowed: /api/appeal
2023-01-06 01:04:48,012 WARNING "POST /api/appeal HTTP/1.1" 405 55
2023-01-06 01:07:28,002 WARNING Forbidden: /api/appeal
2023-01-06 01:07:28,005 WARNING "PATCH /api/appeal HTTP/1.1" 403 45
2023-01-06 02:04:15,092 WARNING Forbidden: /api/appeal
2023-01-06 02:04:15,096 WARNING "PATCH /api/appeal HTTP/1.1" 403 45
2023-01-06 02:10:12,952 WARNING Unsupported Media Type: /api/appeal
2023-01-06 02:10:12,954 WARNING "PATCH /api/appeal HTTP/1.1" 415 113
2023-01-06 02:11:16,449 WARNING Unsupported Media Type: /api/appeal
2023-01-06 02:11:16,453 WARNING "PATCH /api/appeal HTTP/1.1" 415 113
2023-01-06 02:11:31,307 WARNING Unsupported Media Type: /api/appeal
2023-01-06 02:11:31,310 WARNING "PATCH /api/appeal HTTP/1.1" 415 113
2023-01-06 02:20:34,909 WARNING Forbidden: /api/appeal
2023-01-06 02:20:34,912 WARNING "PATCH /api/appeal HTTP/1.1" 403 82
2023-01-06 02:22:01,192 WARNING Forbidden: /api/appeal
2023-01-06 02:22:01,194 WARNING "PATCH /api/appeal HTTP/1.1" 403 82
2023-01-06 02:24:00,957 ERROR Internal Server Error: /api/appeal
Traceback (most recent call last):
  File "C:\Users\HP\PycharmProjects\git_push\venv\lib\site-packages\django\core\handlers\exception.py", line 55, in inner
    response = get_response(request)
  File "C:\Users\HP\PycharmProjects\git_push\venv\lib\site-packages\django\core\handlers\base.py", line 197, in _get_response
    response = wrapped_callback(request, *callback_args, **callback_kwargs)
  File "C:\Users\HP\PycharmProjects\git_push\venv\lib\site-packages\django\views\decorators\csrf.py", line 54, in wrapped_view
    return view_func(*args, **kwargs)
  File "C:\Users\HP\PycharmProjects\git_push\venv\lib\site-packages\django\views\generic\base.py", line 84, in view
    return self.dispatch(request, *args, **kwargs)
  File "C:\Users\HP\PycharmProjects\git_push\venv\lib\site-packages\rest_framework\views.py", line 509, in dispatch
    response = self.handle_exception(exc)
  File "C:\Users\HP\PycharmProjects\git_push\venv\lib\site-packages\rest_framework\views.py", line 469, in handle_exception
    self.raise_uncaught_exception(exc)
  File "C:\Users\HP\PycharmProjects\git_push\venv\lib\site-packages\rest_framework\views.py", line 480, in raise_uncaught_exception
    raise exc
  File "C:\Users\HP\PycharmProjects\git_push\venv\lib\site-packages\rest_framework\views.py", line 506, in dispatch
    response = handler(request, *args, **kwargs)
  File "C:\Users\HP\PycharmProjects\git_push\online_reception_of_appeals\mysite\home\views.py", line 175, in get
    print(request.user.session_id)
  File "C:\Users\HP\PycharmProjects\git_push\venv\lib\site-packages\django\utils\functional.py", line 259, in inner
    return func(self._wrapped, *args)
AttributeError: 'User' object has no attribute 'session_id'
2023-01-06 02:24:00,974 ERROR "GET /api/appeal HTTP/1.1" 500 97428
2023-01-06 02:24:12,101 ERROR Internal Server Error: /api/appeal
Traceback (most recent call last):
  File "C:\Users\HP\PycharmProjects\git_push\venv\lib\site-packages\django\core\handlers\exception.py", line 55, in inner
    response = get_response(request)
  File "C:\Users\HP\PycharmProjects\git_push\venv\lib\site-packages\django\core\handlers\base.py", line 197, in _get_response
    response = wrapped_callback(request, *callback_args, **callback_kwargs)
  File "C:\Users\HP\PycharmProjects\git_push\venv\lib\site-packages\django\views\decorators\csrf.py", line 54, in wrapped_view
    return view_func(*args, **kwargs)
  File "C:\Users\HP\PycharmProjects\git_push\venv\lib\site-packages\django\views\generic\base.py", line 84, in view
    return self.dispatch(request, *args, **kwargs)
  File "C:\Users\HP\PycharmProjects\git_push\venv\lib\site-packages\rest_framework\views.py", line 509, in dispatch
    response = self.handle_exception(exc)
  File "C:\Users\HP\PycharmProjects\git_push\venv\lib\site-packages\rest_framework\views.py", line 469, in handle_exception
    self.raise_uncaught_exception(exc)
  File "C:\Users\HP\PycharmProjects\git_push\venv\lib\site-packages\rest_framework\views.py", line 480, in raise_uncaught_exception
    raise exc
  File "C:\Users\HP\PycharmProjects\git_push\venv\lib\site-packages\rest_framework\views.py", line 506, in dispatch
    response = handler(request, *args, **kwargs)
  File "C:\Users\HP\PycharmProjects\git_push\online_reception_of_appeals\mysite\home\views.py", line 175, in get
    print(request.user.sessionid)
  File "C:\Users\HP\PycharmProjects\git_push\venv\lib\site-packages\django\utils\functional.py", line 259, in inner
    return func(self._wrapped, *args)
AttributeError: 'User' object has no attribute 'sessionid'
2023-01-06 02:24:12,122 ERROR "GET /api/appeal HTTP/1.1" 500 97419
2023-01-06 02:24:24,649 ERROR Internal Server Error: /api/appeal
Traceback (most recent call last):
  File "C:\Users\HP\PycharmProjects\git_push\venv\lib\site-packages\django\core\handlers\exception.py", line 55, in inner
    response = get_response(request)
  File "C:\Users\HP\PycharmProjects\git_push\venv\lib\site-packages\django\core\handlers\base.py", line 197, in _get_response
    response = wrapped_callback(request, *callback_args, **callback_kwargs)
  File "C:\Users\HP\PycharmProjects\git_push\venv\lib\site-packages\django\views\decorators\csrf.py", line 54, in wrapped_view
    return view_func(*args, **kwargs)
  File "C:\Users\HP\PycharmProjects\git_push\venv\lib\site-packages\django\views\generic\base.py", line 84, in view
    return self.dispatch(request, *args, **kwargs)
  File "C:\Users\HP\PycharmProjects\git_push\venv\lib\site-packages\rest_framework\views.py", line 509, in dispatch
    response = self.handle_exception(exc)
  File "C:\Users\HP\PycharmProjects\git_push\venv\lib\site-packages\rest_framework\views.py", line 469, in handle_exception
    self.raise_uncaught_exception(exc)
  File "C:\Users\HP\PycharmProjects\git_push\venv\lib\site-packages\rest_framework\views.py", line 480, in raise_uncaught_exception
    raise exc
  File "C:\Users\HP\PycharmProjects\git_push\venv\lib\site-packages\rest_framework\views.py", line 506, in dispatch
    response = handler(request, *args, **kwargs)
  File "C:\Users\HP\PycharmProjects\git_push\online_reception_of_appeals\mysite\home\views.py", line 175, in get
    print(request.user.cookie)
  File "C:\Users\HP\PycharmProjects\git_push\venv\lib\site-packages\django\utils\functional.py", line 259, in inner
    return func(self._wrapped, *args)
AttributeError: 'User' object has no attribute 'cookie'
2023-01-06 02:24:24,669 ERROR "GET /api/appeal HTTP/1.1" 500 97385
2023-01-06 02:27:05,085 WARNING Forbidden: /api/appeal
2023-01-06 02:27:05,087 WARNING "GET /api/appeal HTTP/1.1" 403 82
2023-01-06 02:27:05,104 WARNING Forbidden: /api/appeal
2023-01-06 02:27:05,106 WARNING "PATCH /api/appeal HTTP/1.1" 403 46
2023-01-06 02:27:18,062 WARNING Forbidden: /api/appeal
2023-01-06 02:27:18,065 WARNING "GET /api/appeal HTTP/1.1" 403 82
2023-01-06 02:28:19,116 WARNING Forbidden: /api/appeal
2023-01-06 02:28:19,119 WARNING "PATCH /api/appeal HTTP/1.1" 403 46
2023-01-06 02:30:52,924 WARNING Forbidden: /api/appeal
2023-01-06 02:30:52,926 WARNING "PATCH /api/appeal HTTP/1.1" 403 46
2023-01-06 15:31:01,136 WARNING Forbidden: /api/appeal
2023-01-06 15:31:01,139 WARNING "GET /api/appeal HTTP/1.1" 403 82
2023-01-06 15:35:29,313 WARNING Forbidden: /api/appeal
2023-01-06 15:35:29,317 WARNING "GET /api/appeal HTTP/1.1" 403 231
2023-01-06 15:35:44,196 WARNING Forbidden: /api/appeal
2023-01-06 15:35:44,199 WARNING "GET /api/appeal HTTP/1.1" 403 82
2023-01-06 15:35:55,802 WARNING Forbidden: /api/appeal
2023-01-06 15:35:55,806 WARNING "GET /api/appeal HTTP/1.1" 403 231
2023-01-06 15:53:32,238 WARNING Not Found: /js/chunk-vendors.js
2023-01-06 15:53:32,240 WARNING "GET /js/chunk-vendors.js HTTP/1.1" 404 5976
2023-01-06 15:53:32,529 WARNING Not Found: /js/app.js
2023-01-06 15:53:32,532 WARNING "GET /js/app.js HTTP/1.1" 404 5946
2023-01-06 15:57:25,270 ERROR Internal Server Error: /api/appeal
Traceback (most recent call last):
  File "C:\Users\HP\PycharmProjects\git_push\venv\lib\site-packages\rest_framework\request.py", line 416, in __getattr__
    return getattr(self._request, attr)
AttributeError: 'WSGIRequest' object has no attribute 'COOKIE'

During handling of the above exception, another exception occurred:

Traceback (most recent call last):
  File "C:\Users\HP\PycharmProjects\git_push\venv\lib\site-packages\django\core\handlers\exception.py", line 55, in inner
    response = get_response(request)
  File "C:\Users\HP\PycharmProjects\git_push\venv\lib\site-packages\django\core\handlers\base.py", line 197, in _get_response
    response = wrapped_callback(request, *callback_args, **callback_kwargs)
  File "C:\Users\HP\PycharmProjects\git_push\venv\lib\site-packages\django\views\decorators\csrf.py", line 54, in wrapped_view
    return view_func(*args, **kwargs)
  File "C:\Users\HP\PycharmProjects\git_push\venv\lib\site-packages\django\views\generic\base.py", line 84, in view
    return self.dispatch(request, *args, **kwargs)
  File "C:\Users\HP\PycharmProjects\git_push\venv\lib\site-packages\rest_framework\views.py", line 509, in dispatch
    response = self.handle_exception(exc)
  File "C:\Users\HP\PycharmProjects\git_push\venv\lib\site-packages\rest_framework\views.py", line 469, in handle_exception
    self.raise_uncaught_exception(exc)
  File "C:\Users\HP\PycharmProjects\git_push\venv\lib\site-packages\rest_framework\views.py", line 480, in raise_uncaught_exception
    raise exc
  File "C:\Users\HP\PycharmProjects\git_push\venv\lib\site-packages\rest_framework\views.py", line 506, in dispatch
    response = handler(request, *args, **kwargs)
  File "C:\Users\HP\PycharmProjects\git_push\online_reception_of_appeals\mysite\home\views.py", line 156, in get
    print(request.COOKIE)
  File "C:\Users\HP\PycharmProjects\git_push\venv\lib\site-packages\rest_framework\request.py", line 418, in __getattr__
    return self.__getattribute__(attr)
AttributeError: 'Request' object has no attribute 'COOKIE'
2023-01-06 15:57:25,286 ERROR "GET /api/appeal HTTP/1.1" 500 101647
2023-01-06 15:59:37,070 WARNING Forbidden: /api/appeal
2023-01-06 15:59:37,072 WARNING "GET /api/appeal HTTP/1.1" 403 82
2023-01-06 16:02:55,340 WARNING Forbidden: /api/appeal
2023-01-06 16:02:55,342 WARNING "POST /api/appeal HTTP/1.1" 403 82
2023-01-06 16:03:05,728 WARNING Forbidden: /api/appeal
2023-01-06 16:03:05,730 WARNING "POST /api/appeal HTTP/1.1" 403 46
2023-01-06 16:04:14,927 WARNING Unsupported Media Type: /api/appeal
2023-01-06 16:04:14,929 WARNING "POST /api/appeal HTTP/1.1" 415 99
2023-01-06 16:05:05,856 WARNING Forbidden: /api/appeal
2023-01-06 16:05:05,859 WARNING "POST /api/appeal HTTP/1.1" 403 45
2023-01-06 16:05:19,209 WARNING Unsupported Media Type: /api/appeal
2023-01-06 16:05:19,211 WARNING "POST /api/appeal HTTP/1.1" 415 99
2023-01-06 16:05:28,300 WARNING Forbidden: /api/appeal
2023-01-06 16:05:28,303 WARNING "POST /api/appeal HTTP/1.1" 403 45
2023-01-06 16:05:49,289 WARNING Forbidden: /api/appeal
2023-01-06 16:05:49,291 WARNING "POST /api/appeal HTTP/1.1" 403 45
2023-01-06 16:06:20,525 WARNING Forbidden: /api/appeal
2023-01-06 16:06:20,527 WARNING "POST /api/appeal HTTP/1.1" 403 45
2023-01-06 16:06:35,939 WARNING Bad Request: /api/appeal
2023-01-06 16:06:35,942 WARNING "POST /api/appeal HTTP/1.1" 400 18
2023-01-06 16:08:09,999 WARNING Forbidden: /api/appeal/7
2023-01-06 16:08:10,000 WARNING "PATCH /api/appeal/7 HTTP/1.1" 403 82
2023-01-06 16:08:21,520 WARNING Forbidden: /api/appeal/7
2023-01-06 16:08:21,522 WARNING "PATCH /api/appeal/7 HTTP/1.1" 403 45
2023-01-06 16:08:35,667 ERROR Internal Server Error: /api/appeal/7
Traceback (most recent call last):
  File "C:\Users\HP\PycharmProjects\git_push\venv\lib\site-packages\django\core\handlers\exception.py", line 55, in inner
    response = get_response(request)
  File "C:\Users\HP\PycharmProjects\git_push\venv\lib\site-packages\django\core\handlers\base.py", line 197, in _get_response
    response = wrapped_callback(request, *callback_args, **callback_kwargs)
  File "C:\Users\HP\PycharmProjects\git_push\venv\lib\site-packages\django\views\decorators\csrf.py", line 54, in wrapped_view
    return view_func(*args, **kwargs)
  File "C:\Users\HP\PycharmProjects\git_push\venv\lib\site-packages\django\views\generic\base.py", line 84, in view
    return self.dispatch(request, *args, **kwargs)
  File "C:\Users\HP\PycharmProjects\git_push\venv\lib\site-packages\rest_framework\views.py", line 509, in dispatch
    response = self.handle_exception(exc)
  File "C:\Users\HP\PycharmProjects\git_push\venv\lib\site-packages\rest_framework\views.py", line 469, in handle_exception
    self.raise_uncaught_exception(exc)
  File "C:\Users\HP\PycharmProjects\git_push\venv\lib\site-packages\rest_framework\views.py", line 480, in raise_uncaught_exception
    raise exc
  File "C:\Users\HP\PycharmProjects\git_push\venv\lib\site-packages\rest_framework\views.py", line 506, in dispatch
    response = handler(request, *args, **kwargs)
TypeError: APIAppealDetail.patch() got an unexpected keyword argument 'id'
2023-01-06 16:08:35,676 ERROR "PATCH /api/appeal/7 HTTP/1.1" 500 88609
2023-01-06 16:08:59,465 ERROR Internal Server Error: /api/appeal/7
Traceback (most recent call last):
  File "C:\Users\HP\PycharmProjects\git_push\venv\lib\site-packages\django\core\handlers\exception.py", line 55, in inner
    response = get_response(request)
  File "C:\Users\HP\PycharmProjects\git_push\venv\lib\site-packages\django\core\handlers\base.py", line 197, in _get_response
    response = wrapped_callback(request, *callback_args, **callback_kwargs)
  File "C:\Users\HP\PycharmProjects\git_push\venv\lib\site-packages\django\views\decorators\csrf.py", line 54, in wrapped_view
    return view_func(*args, **kwargs)
  File "C:\Users\HP\PycharmProjects\git_push\venv\lib\site-packages\django\views\generic\base.py", line 84, in view
    return self.dispatch(request, *args, **kwargs)
  File "C:\Users\HP\PycharmProjects\git_push\venv\lib\site-packages\rest_framework\views.py", line 509, in dispatch
    response = self.handle_exception(exc)
  File "C:\Users\HP\PycharmProjects\git_push\venv\lib\site-packages\rest_framework\views.py", line 469, in handle_exception
    self.raise_uncaught_exception(exc)
  File "C:\Users\HP\PycharmProjects\git_push\venv\lib\site-packages\rest_framework\views.py", line 480, in raise_uncaught_exception
    raise exc
  File "C:\Users\HP\PycharmProjects\git_push\venv\lib\site-packages\rest_framework\views.py", line 506, in dispatch
    response = handler(request, *args, **kwargs)
TypeError: APIAppealDetail.patch() got an unexpected keyword argument 'id'
2023-01-06 16:08:59,472 ERROR "PATCH /api/appeal/7 HTTP/1.1" 500 88609
2023-01-06 16:11:57,280 WARNING Bad Request: /api/appeal/7
2023-01-06 16:11:57,283 WARNING "PATCH /api/appeal/7 HTTP/1.1" 400 73
2023-01-06 16:12:22,290 WARNING Bad Request: /api/appeal/7
2023-01-06 16:12:22,293 WARNING "PATCH /api/appeal/7 HTTP/1.1" 400 73
2023-01-06 16:18:16,798 WARNING Not Found: /api/appeal/17
2023-01-06 16:18:16,801 WARNING "DELETE /api/appeal/17 HTTP/1.1" 404 50
2023-01-06 16:40:59,363 WARNING Method Not Allowed: /api/appeal
2023-01-06 16:40:59,366 WARNING "PATCH /api/appeal HTTP/1.1" 405 56
2023-01-06 16:41:38,644 WARNING Forbidden: /api/appeal/12
2023-01-06 16:41:38,648 WARNING "PATCH /api/appeal/12 HTTP/1.1" 403 82
2023-01-06 16:42:12,957 ERROR Internal Server Error: /api/appeal/7
Traceback (most recent call last):
  File "C:\Users\HP\PycharmProjects\git_push\venv\lib\site-packages\django\core\handlers\exception.py", line 55, in inner
    response = get_response(request)
  File "C:\Users\HP\PycharmProjects\git_push\venv\lib\site-packages\django\core\handlers\base.py", line 197, in _get_response
    response = wrapped_callback(request, *callback_args, **callback_kwargs)
  File "C:\Users\HP\PycharmProjects\git_push\venv\lib\site-packages\django\views\decorators\csrf.py", line 54, in wrapped_view
    return view_func(*args, **kwargs)
  File "C:\Users\HP\PycharmProjects\git_push\venv\lib\site-packages\django\views\generic\base.py", line 84, in view
    return self.dispatch(request, *args, **kwargs)
  File "C:\Users\HP\PycharmProjects\git_push\venv\lib\site-packages\rest_framework\views.py", line 509, in dispatch
    response = self.handle_exception(exc)
  File "C:\Users\HP\PycharmProjects\git_push\venv\lib\site-packages\rest_framework\views.py", line 469, in handle_exception
    self.raise_uncaught_exception(exc)
  File "C:\Users\HP\PycharmProjects\git_push\venv\lib\site-packages\rest_framework\views.py", line 480, in raise_uncaught_exception
    raise exc
  File "C:\Users\HP\PycharmProjects\git_push\venv\lib\site-packages\rest_framework\views.py", line 506, in dispatch
    response = handler(request, *args, **kwargs)
  File "C:\Users\HP\PycharmProjects\git_push\online_reception_of_appeals\mysite\home\views.py", line 183, in patch
    if request.data['status'] not in [
KeyError: 'status'
2023-01-06 16:42:12,967 ERROR "PATCH /api/appeal/7 HTTP/1.1" 500 92252
2023-01-06 16:42:49,825 WARNING Forbidden: /api/appeal/7
2023-01-06 16:42:49,827 WARNING "PATCH /api/appeal/7 HTTP/1.1" 403 45
2023-01-06 16:43:04,032 WARNING Forbidden: /api/appeal/12
2023-01-06 16:43:04,034 WARNING "PATCH /api/appeal/12 HTTP/1.1" 403 82
2023-01-06 16:45:49,042 ERROR Internal Server Error: /api/appeal
Traceback (most recent call last):
  File "C:\Users\HP\PycharmProjects\git_push\venv\lib\site-packages\django\core\handlers\exception.py", line 55, in inner
    response = get_response(request)
  File "C:\Users\HP\PycharmProjects\git_push\venv\lib\site-packages\django\core\handlers\base.py", line 197, in _get_response
    response = wrapped_callback(request, *callback_args, **callback_kwargs)
  File "C:\Users\HP\PycharmProjects\git_push\venv\lib\site-packages\django\views\decorators\csrf.py", line 54, in wrapped_view
    return view_func(*args, **kwargs)
  File "C:\Users\HP\PycharmProjects\git_push\venv\lib\site-packages\django\views\generic\base.py", line 84, in view
    return self.dispatch(request, *args, **kwargs)
  File "C:\Users\HP\PycharmProjects\git_push\venv\lib\site-packages\rest_framework\views.py", line 509, in dispatch
    response = self.handle_exception(exc)
  File "C:\Users\HP\PycharmProjects\git_push\venv\lib\site-packages\rest_framework\views.py", line 469, in handle_exception
    self.raise_uncaught_exception(exc)
  File "C:\Users\HP\PycharmProjects\git_push\venv\lib\site-packages\rest_framework\views.py", line 480, in raise_uncaught_exception
    raise exc
  File "C:\Users\HP\PycharmProjects\git_push\venv\lib\site-packages\rest_framework\views.py", line 506, in dispatch
    response = handler(request, *args, **kwargs)
  File "C:\Users\HP\PycharmProjects\git_push\online_reception_of_appeals\mysite\home\views.py", line 156, in get
    if request.user.is_authentificated():
  File "C:\Users\HP\PycharmProjects\git_push\venv\lib\site-packages\django\utils\functional.py", line 259, in inner
    return func(self._wrapped, *args)
AttributeError: 'User' object has no attribute 'is_authentificated'
2023-01-06 16:45:49,062 ERROR "GET /api/appeal HTTP/1.1" 500 97488
2023-01-06 16:49:16,223 WARNING Forbidden: /api/appeal/12
2023-01-06 16:49:16,226 WARNING "GET /api/appeal/12 HTTP/1.1" 403 82
2023-01-06 16:49:42,586 WARNING Forbidden: /api/appeal/12
2023-01-06 16:49:42,589 WARNING "GET /api/appeal/12 HTTP/1.1" 403 82
2023-01-06 16:50:03,052 WARNING Not Found: /api/appeal/
2023-01-06 16:50:03,056 WARNING "GET /api/appeal/ HTTP/1.1" 404 6040
2023-01-06 16:50:18,776 WARNING Forbidden: /api/appeal
2023-01-06 16:50:18,779 WARNING "GET /api/appeal HTTP/1.1" 403 26
2023-01-08 01:43:22,090 ERROR Internal Server Error: /api/appeal
Traceback (most recent call last):
  File "C:\Users\HP\PycharmProjects\git_push\venv\lib\site-packages\django\db\backends\utils.py", line 89, in _execute
    return self.cursor.execute(sql, params)
  File "C:\Users\HP\PycharmProjects\git_push\venv\lib\site-packages\django\db\backends\sqlite3\base.py", line 477, in execute
    return Database.Cursor.execute(self, query, params)
sqlite3.IntegrityError: CHECK constraint failed: appeal_option_constraint

The above exception was the direct cause of the following exception:

Traceback (most recent call last):
  File "C:\Users\HP\PycharmProjects\git_push\venv\lib\site-packages\django\core\handlers\exception.py", line 55, in inner
    response = get_response(request)
  File "C:\Users\HP\PycharmProjects\git_push\venv\lib\site-packages\django\core\handlers\base.py", line 197, in _get_response
    response = wrapped_callback(request, *callback_args, **callback_kwargs)
  File "C:\Users\HP\PycharmProjects\git_push\venv\lib\site-packages\django\views\decorators\csrf.py", line 54, in wrapped_view
    return view_func(*args, **kwargs)
  File "C:\Users\HP\PycharmProjects\git_push\venv\lib\site-packages\django\views\generic\base.py", line 84, in view
    return self.dispatch(request, *args, **kwargs)
  File "C:\Users\HP\PycharmProjects\git_push\venv\lib\site-packages\rest_framework\views.py", line 509, in dispatch
    response = self.handle_exception(exc)
  File "C:\Users\HP\PycharmProjects\git_push\venv\lib\site-packages\rest_framework\views.py", line 469, in handle_exception
    self.raise_uncaught_exception(exc)
  File "C:\Users\HP\PycharmProjects\git_push\venv\lib\site-packages\rest_framework\views.py", line 480, in raise_uncaught_exception
    raise exc
  File "C:\Users\HP\PycharmProjects\git_push\venv\lib\site-packages\rest_framework\views.py", line 506, in dispatch
    response = handler(request, *args, **kwargs)
  File "C:\Users\HP\PycharmProjects\git_push\online_reception_of_appeals\mysite\home\views.py", line 162, in post
    serializer.save()
  File "C:\Users\HP\PycharmProjects\git_push\venv\lib\site-packages\rest_framework\serializers.py", line 212, in save
    self.instance = self.create(validated_data)
  File "C:\Users\HP\PycharmProjects\git_push\online_reception_of_appeals\mysite\home\serializers.py", line 48, in create
    return Appeal.objects.create(**validated_data)
  File "C:\Users\HP\PycharmProjects\git_push\venv\lib\site-packages\django\db\models\manager.py", line 85, in manager_method
    return getattr(self.get_queryset(), name)(*args, **kwargs)
  File "C:\Users\HP\PycharmProjects\git_push\venv\lib\site-packages\django\db\models\query.py", line 514, in create
    obj.save(force_insert=True, using=self.db)
  File "C:\Users\HP\PycharmProjects\git_push\venv\lib\site-packages\django\db\models\base.py", line 806, in save
    self.save_base(
  File "C:\Users\HP\PycharmProjects\git_push\venv\lib\site-packages\django\db\models\base.py", line 857, in save_base
    updated = self._save_table(
  File "C:\Users\HP\PycharmProjects\git_push\venv\lib\site-packages\django\db\models\base.py", line 1000, in _save_table
    results = self._do_insert(
  File "C:\Users\HP\PycharmProjects\git_push\venv\lib\site-packages\django\db\models\base.py", line 1041, in _do_insert
    return manager._insert(
  File "C:\Users\HP\PycharmProjects\git_push\venv\lib\site-packages\django\db\models\manager.py", line 85, in manager_method
    return getattr(self.get_queryset(), name)(*args, **kwargs)
  File "C:\Users\HP\PycharmProjects\git_push\venv\lib\site-packages\django\db\models\query.py", line 1434, in _insert
    return query.get_compiler(using=using).execute_sql(returning_fields)
  File "C:\Users\HP\PycharmProjects\git_push\venv\lib\site-packages\django\db\models\sql\compiler.py", line 1621, in execute_sql
    cursor.execute(sql, params)
  File "C:\Users\HP\PycharmProjects\git_push\venv\lib\site-packages\django\db\backends\utils.py", line 103, in execute
    return super().execute(sql, params)
  File "C:\Users\HP\PycharmProjects\git_push\venv\lib\site-packages\django\db\backends\utils.py", line 67, in execute
    return self._execute_with_wrappers(
  File "C:\Users\HP\PycharmProjects\git_push\venv\lib\site-packages\django\db\backends\utils.py", line 80, in _execute_with_wrappers
    return executor(sql, params, many, context)
  File "C:\Users\HP\PycharmProjects\git_push\venv\lib\site-packages\django\db\backends\utils.py", line 84, in _execute
    with self.db.wrap_database_errors:
  File "C:\Users\HP\PycharmProjects\git_push\venv\lib\site-packages\django\db\utils.py", line 91, in __exit__
    raise dj_exc_value.with_traceback(traceback) from exc_value
  File "C:\Users\HP\PycharmProjects\git_push\venv\lib\site-packages\django\db\backends\utils.py", line 89, in _execute
    return self.cursor.execute(sql, params)
  File "C:\Users\HP\PycharmProjects\git_push\venv\lib\site-packages\django\db\backends\sqlite3\base.py", line 477, in execute
    return Database.Cursor.execute(self, query, params)
django.db.utils.IntegrityError: CHECK constraint failed: appeal_option_constraint
2023-01-08 01:43:22,243 ERROR "POST /api/appeal HTTP/1.1" 500 189610
2023-01-08 01:49:06,390 WARNING Bad Request: /api/appeal
2023-01-08 01:49:06,400 WARNING "POST /api/appeal HTTP/1.1" 400 24
2023-01-08 01:51:32,419 WARNING Method Not Allowed: /api/appeal
2023-01-08 01:51:32,425 WARNING "PATCH /api/appeal HTTP/1.1" 405 56
2023-01-08 01:51:54,623 WARNING Method Not Allowed: /api/appeal
2023-01-08 01:51:54,632 WARNING "PATCH /api/appeal HTTP/1.1" 405 56
2023-01-08 01:52:27,048 WARNING Not Found: /js/app.js
2023-01-08 01:52:27,060 WARNING Not Found: /js/chunk-vendors.js
2023-01-08 01:52:27,064 WARNING "GET /js/app.js HTTP/1.1" 404 5946
2023-01-08 01:52:27,074 WARNING "GET /js/chunk-vendors.js HTTP/1.1" 404 5976
2023-01-08 01:53:26,420 WARNING Method Not Allowed: /api/appeal
2023-01-08 01:53:26,432 WARNING "PATCH /api/appeal HTTP/1.1" 405 56
2023-01-08 01:53:29,604 WARNING Not Found: /js/chunk-vendors.js
2023-01-08 01:53:29,614 WARNING Not Found: /js/app.js
2023-01-08 01:53:29,619 WARNING "GET /js/chunk-vendors.js HTTP/1.1" 404 5976
2023-01-08 01:53:29,636 WARNING "GET /js/app.js HTTP/1.1" 404 5946
2023-01-08 01:54:30,710 WARNING Not Found: /js/chunk-vendors.js
2023-01-08 01:54:30,718 WARNING Not Found: /js/app.js
2023-01-08 01:54:30,722 WARNING "GET /js/chunk-vendors.js HTTP/1.1" 404 5976
2023-01-08 01:54:30,726 WARNING "GET /js/app.js HTTP/1.1" 404 5946
2023-01-08 01:58:23,004 WARNING Bad Request: /api/appeal/15
2023-01-08 01:58:23,019 WARNING "PATCH /api/appeal/15 HTTP/1.1" 400 20
2023-01-10 11:07:26,928 WARNING Not Found: /appeal/<%= BASE_URL %>favicon.ico
2023-01-10 11:07:26,929 WARNING "GET /appeal/%3C%=%20BASE_URL%20%%3Efavicon.ico HTTP/1.1" 404 6044
2023-01-10 11:07:29,205 WARNING Not Found: /appeal/<%= BASE_URL %>favicon.ico
2023-01-10 11:07:29,205 WARNING "GET /appeal/%3C%=%20BASE_URL%20%%3Efavicon.ico HTTP/1.1" 404 6044
2023-01-10 11:07:41,392 WARNING Not Found: /appeal/<%= BASE_URL %>favicon.ico
2023-01-10 11:07:41,393 WARNING "GET /appeal/%3C%=%20BASE_URL%20%%3Efavicon.ico HTTP/1.1" 404 6044
2023-01-10 11:08:58,971 WARNING Not Found: /appeal/<%= BASE_URL %>favicon.ico
2023-01-10 11:08:58,972 WARNING "GET /appeal/%3C%=%20BASE_URL%20%%3Efavicon.ico HTTP/1.1" 404 6044
2023-01-10 11:09:00,228 WARNING Not Found: /appeal/<%= BASE_URL %>favicon.ico
2023-01-10 11:09:00,229 WARNING "GET /appeal/%3C%=%20BASE_URL%20%%3Efavicon.ico HTTP/1.1" 404 6044
2023-01-10 11:09:00,896 WARNING Not Found: /appeal/<%= BASE_URL %>favicon.ico
2023-01-10 11:09:00,897 WARNING "GET /appeal/%3C%=%20BASE_URL%20%%3Efavicon.ico HTTP/1.1" 404 6044
2023-01-10 11:09:21,621 ERROR Internal Server Error: /appeal/
Traceback (most recent call last):
  File "/Library/Frameworks/Python.framework/Versions/3.10/lib/python3.10/site-packages/django/core/handlers/exception.py", line 55, in inner
    response = get_response(request)
  File "/Library/Frameworks/Python.framework/Versions/3.10/lib/python3.10/site-packages/django/core/handlers/base.py", line 220, in _get_response
    response = response.render()
  File "/Library/Frameworks/Python.framework/Versions/3.10/lib/python3.10/site-packages/django/template/response.py", line 114, in render
    self.content = self.rendered_content
  File "/Library/Frameworks/Python.framework/Versions/3.10/lib/python3.10/site-packages/django/template/response.py", line 92, in rendered_content
    return template.render(context, self._request)
  File "/Library/Frameworks/Python.framework/Versions/3.10/lib/python3.10/site-packages/django/template/backends/django.py", line 62, in render
    return self.template.render(context)
  File "/Library/Frameworks/Python.framework/Versions/3.10/lib/python3.10/site-packages/django/template/base.py", line 175, in render
    return self._render(context)
  File "/Library/Frameworks/Python.framework/Versions/3.10/lib/python3.10/site-packages/django/template/base.py", line 167, in _render
    return self.nodelist.render(context)
  File "/Library/Frameworks/Python.framework/Versions/3.10/lib/python3.10/site-packages/django/template/base.py", line 1000, in render
    return SafeString("".join([node.render_annotated(context) for node in self]))
  File "/Library/Frameworks/Python.framework/Versions/3.10/lib/python3.10/site-packages/django/template/base.py", line 1000, in <listcomp>
    return SafeString("".join([node.render_annotated(context) for node in self]))
  File "/Library/Frameworks/Python.framework/Versions/3.10/lib/python3.10/site-packages/django/template/base.py", line 958, in render_annotated
    return self.render(context)
  File "/Library/Frameworks/Python.framework/Versions/3.10/lib/python3.10/site-packages/django/template/library.py", line 239, in render
    output = self.func(*resolved_args, **resolved_kwargs)
  File "/Library/Frameworks/Python.framework/Versions/3.10/lib/python3.10/site-packages/webpack_loader/templatetags/webpack_loader.py", line 12, in render_bundle
    tags = utils.get_as_tags(bundle_name, extension=extension, config=config, attrs=attrs)
  File "/Library/Frameworks/Python.framework/Versions/3.10/lib/python3.10/site-packages/webpack_loader/utils.py", line 62, in get_as_tags
    bundle = _get_bundle(bundle_name, extension, config)
  File "/Library/Frameworks/Python.framework/Versions/3.10/lib/python3.10/site-packages/webpack_loader/utils.py", line 40, in _get_bundle
    bundle = get_loader(config).get_bundle(bundle_name)
  File "/Library/Frameworks/Python.framework/Versions/3.10/lib/python3.10/site-packages/webpack_loader/loader.py", line 96, in get_bundle
    raise WebpackError(error)
webpack_loader.exceptions.WebpackError: 
            ModuleNotFoundError in 
            Module not found: Error: Can't resolve 'path' in '/Users/deniskanukov/online_reception_of_appeals/mysite/frontend/node_modules/convert-source-map'

BREAKING CHANGE: webpack < 5 used to include polyfills for node.js core modules by default.
This is no longer the case. Verify if you need this module and configure a polyfill for it.

If you want to include a polyfill, you need to:
	- add a fallback 'resolve.fallback: { "path": require.resolve("path-browserify") }'
	- install 'path-browserify'
If you don't want to include a polyfill, you can use an empty module like this:
	resolve.fallback: { "path": false }
            
2023-01-10 11:09:21,630 ERROR "GET /appeal/ HTTP/1.1" 500 125080
2023-01-10 11:09:23,029 ERROR Internal Server Error: /appeal/
Traceback (most recent call last):
  File "/Library/Frameworks/Python.framework/Versions/3.10/lib/python3.10/site-packages/django/core/handlers/exception.py", line 55, in inner
    response = get_response(request)
  File "/Library/Frameworks/Python.framework/Versions/3.10/lib/python3.10/site-packages/django/core/handlers/base.py", line 220, in _get_response
    response = response.render()
  File "/Library/Frameworks/Python.framework/Versions/3.10/lib/python3.10/site-packages/django/template/response.py", line 114, in render
    self.content = self.rendered_content
  File "/Library/Frameworks/Python.framework/Versions/3.10/lib/python3.10/site-packages/django/template/response.py", line 92, in rendered_content
    return template.render(context, self._request)
  File "/Library/Frameworks/Python.framework/Versions/3.10/lib/python3.10/site-packages/django/template/backends/django.py", line 62, in render
    return self.template.render(context)
  File "/Library/Frameworks/Python.framework/Versions/3.10/lib/python3.10/site-packages/django/template/base.py", line 175, in render
    return self._render(context)
  File "/Library/Frameworks/Python.framework/Versions/3.10/lib/python3.10/site-packages/django/template/base.py", line 167, in _render
    return self.nodelist.render(context)
  File "/Library/Frameworks/Python.framework/Versions/3.10/lib/python3.10/site-packages/django/template/base.py", line 1000, in render
    return SafeString("".join([node.render_annotated(context) for node in self]))
  File "/Library/Frameworks/Python.framework/Versions/3.10/lib/python3.10/site-packages/django/template/base.py", line 1000, in <listcomp>
    return SafeString("".join([node.render_annotated(context) for node in self]))
  File "/Library/Frameworks/Python.framework/Versions/3.10/lib/python3.10/site-packages/django/template/base.py", line 958, in render_annotated
    return self.render(context)
  File "/Library/Frameworks/Python.framework/Versions/3.10/lib/python3.10/site-packages/django/template/library.py", line 239, in render
    output = self.func(*resolved_args, **resolved_kwargs)
  File "/Library/Frameworks/Python.framework/Versions/3.10/lib/python3.10/site-packages/webpack_loader/templatetags/webpack_loader.py", line 12, in render_bundle
    tags = utils.get_as_tags(bundle_name, extension=extension, config=config, attrs=attrs)
  File "/Library/Frameworks/Python.framework/Versions/3.10/lib/python3.10/site-packages/webpack_loader/utils.py", line 62, in get_as_tags
    bundle = _get_bundle(bundle_name, extension, config)
  File "/Library/Frameworks/Python.framework/Versions/3.10/lib/python3.10/site-packages/webpack_loader/utils.py", line 40, in _get_bundle
    bundle = get_loader(config).get_bundle(bundle_name)
  File "/Library/Frameworks/Python.framework/Versions/3.10/lib/python3.10/site-packages/webpack_loader/loader.py", line 96, in get_bundle
    raise WebpackError(error)
webpack_loader.exceptions.WebpackError: 
            ModuleNotFoundError in 
            Module not found: Error: Can't resolve 'path' in '/Users/deniskanukov/online_reception_of_appeals/mysite/frontend/node_modules/convert-source-map'

BREAKING CHANGE: webpack < 5 used to include polyfills for node.js core modules by default.
This is no longer the case. Verify if you need this module and configure a polyfill for it.

If you want to include a polyfill, you need to:
	- add a fallback 'resolve.fallback: { "path": require.resolve("path-browserify") }'
	- install 'path-browserify'
If you don't want to include a polyfill, you can use an empty module like this:
	resolve.fallback: { "path": false }
            
2023-01-10 11:09:23,042 ERROR "GET /appeal/ HTTP/1.1" 500 125080
2023-01-10 11:09:23,799 ERROR Internal Server Error: /appeal/
Traceback (most recent call last):
  File "/Library/Frameworks/Python.framework/Versions/3.10/lib/python3.10/site-packages/django/core/handlers/exception.py", line 55, in inner
    response = get_response(request)
  File "/Library/Frameworks/Python.framework/Versions/3.10/lib/python3.10/site-packages/django/core/handlers/base.py", line 220, in _get_response
    response = response.render()
  File "/Library/Frameworks/Python.framework/Versions/3.10/lib/python3.10/site-packages/django/template/response.py", line 114, in render
    self.content = self.rendered_content
  File "/Library/Frameworks/Python.framework/Versions/3.10/lib/python3.10/site-packages/django/template/response.py", line 92, in rendered_content
    return template.render(context, self._request)
  File "/Library/Frameworks/Python.framework/Versions/3.10/lib/python3.10/site-packages/django/template/backends/django.py", line 62, in render
    return self.template.render(context)
  File "/Library/Frameworks/Python.framework/Versions/3.10/lib/python3.10/site-packages/django/template/base.py", line 175, in render
    return self._render(context)
  File "/Library/Frameworks/Python.framework/Versions/3.10/lib/python3.10/site-packages/django/template/base.py", line 167, in _render
    return self.nodelist.render(context)
  File "/Library/Frameworks/Python.framework/Versions/3.10/lib/python3.10/site-packages/django/template/base.py", line 1000, in render
    return SafeString("".join([node.render_annotated(context) for node in self]))
  File "/Library/Frameworks/Python.framework/Versions/3.10/lib/python3.10/site-packages/django/template/base.py", line 1000, in <listcomp>
    return SafeString("".join([node.render_annotated(context) for node in self]))
  File "/Library/Frameworks/Python.framework/Versions/3.10/lib/python3.10/site-packages/django/template/base.py", line 958, in render_annotated
    return self.render(context)
  File "/Library/Frameworks/Python.framework/Versions/3.10/lib/python3.10/site-packages/django/template/library.py", line 239, in render
    output = self.func(*resolved_args, **resolved_kwargs)
  File "/Library/Frameworks/Python.framework/Versions/3.10/lib/python3.10/site-packages/webpack_loader/templatetags/webpack_loader.py", line 12, in render_bundle
    tags = utils.get_as_tags(bundle_name, extension=extension, config=config, attrs=attrs)
  File "/Library/Frameworks/Python.framework/Versions/3.10/lib/python3.10/site-packages/webpack_loader/utils.py", line 62, in get_as_tags
    bundle = _get_bundle(bundle_name, extension, config)
  File "/Library/Frameworks/Python.framework/Versions/3.10/lib/python3.10/site-packages/webpack_loader/utils.py", line 40, in _get_bundle
    bundle = get_loader(config).get_bundle(bundle_name)
  File "/Library/Frameworks/Python.framework/Versions/3.10/lib/python3.10/site-packages/webpack_loader/loader.py", line 96, in get_bundle
    raise WebpackError(error)
webpack_loader.exceptions.WebpackError: 
            ModuleNotFoundError in 
            Module not found: Error: Can't resolve 'path' in '/Users/deniskanukov/online_reception_of_appeals/mysite/frontend/node_modules/convert-source-map'

BREAKING CHANGE: webpack < 5 used to include polyfills for node.js core modules by default.
This is no longer the case. Verify if you need this module and configure a polyfill for it.

If you want to include a polyfill, you need to:
	- add a fallback 'resolve.fallback: { "path": require.resolve("path-browserify") }'
	- install 'path-browserify'
If you don't want to include a polyfill, you can use an empty module like this:
	resolve.fallback: { "path": false }
            
2023-01-10 11:09:23,808 ERROR "GET /appeal/ HTTP/1.1" 500 125080
2023-01-10 11:09:24,435 ERROR Internal Server Error: /appeal/
Traceback (most recent call last):
  File "/Library/Frameworks/Python.framework/Versions/3.10/lib/python3.10/site-packages/django/core/handlers/exception.py", line 55, in inner
    response = get_response(request)
  File "/Library/Frameworks/Python.framework/Versions/3.10/lib/python3.10/site-packages/django/core/handlers/base.py", line 220, in _get_response
    response = response.render()
  File "/Library/Frameworks/Python.framework/Versions/3.10/lib/python3.10/site-packages/django/template/response.py", line 114, in render
    self.content = self.rendered_content
  File "/Library/Frameworks/Python.framework/Versions/3.10/lib/python3.10/site-packages/django/template/response.py", line 92, in rendered_content
    return template.render(context, self._request)
  File "/Library/Frameworks/Python.framework/Versions/3.10/lib/python3.10/site-packages/django/template/backends/django.py", line 62, in render
    return self.template.render(context)
  File "/Library/Frameworks/Python.framework/Versions/3.10/lib/python3.10/site-packages/django/template/base.py", line 175, in render
    return self._render(context)
  File "/Library/Frameworks/Python.framework/Versions/3.10/lib/python3.10/site-packages/django/template/base.py", line 167, in _render
    return self.nodelist.render(context)
  File "/Library/Frameworks/Python.framework/Versions/3.10/lib/python3.10/site-packages/django/template/base.py", line 1000, in render
    return SafeString("".join([node.render_annotated(context) for node in self]))
  File "/Library/Frameworks/Python.framework/Versions/3.10/lib/python3.10/site-packages/django/template/base.py", line 1000, in <listcomp>
    return SafeString("".join([node.render_annotated(context) for node in self]))
  File "/Library/Frameworks/Python.framework/Versions/3.10/lib/python3.10/site-packages/django/template/base.py", line 958, in render_annotated
    return self.render(context)
  File "/Library/Frameworks/Python.framework/Versions/3.10/lib/python3.10/site-packages/django/template/library.py", line 239, in render
    output = self.func(*resolved_args, **resolved_kwargs)
  File "/Library/Frameworks/Python.framework/Versions/3.10/lib/python3.10/site-packages/webpack_loader/templatetags/webpack_loader.py", line 12, in render_bundle
    tags = utils.get_as_tags(bundle_name, extension=extension, config=config, attrs=attrs)
  File "/Library/Frameworks/Python.framework/Versions/3.10/lib/python3.10/site-packages/webpack_loader/utils.py", line 62, in get_as_tags
    bundle = _get_bundle(bundle_name, extension, config)
  File "/Library/Frameworks/Python.framework/Versions/3.10/lib/python3.10/site-packages/webpack_loader/utils.py", line 40, in _get_bundle
    bundle = get_loader(config).get_bundle(bundle_name)
  File "/Library/Frameworks/Python.framework/Versions/3.10/lib/python3.10/site-packages/webpack_loader/loader.py", line 96, in get_bundle
    raise WebpackError(error)
webpack_loader.exceptions.WebpackError: 
            ModuleNotFoundError in 
            Module not found: Error: Can't resolve 'path' in '/Users/deniskanukov/online_reception_of_appeals/mysite/frontend/node_modules/convert-source-map'

BREAKING CHANGE: webpack < 5 used to include polyfills for node.js core modules by default.
This is no longer the case. Verify if you need this module and configure a polyfill for it.

If you want to include a polyfill, you need to:
	- add a fallback 'resolve.fallback: { "path": require.resolve("path-browserify") }'
	- install 'path-browserify'
If you don't want to include a polyfill, you can use an empty module like this:
	resolve.fallback: { "path": false }
            
2023-01-10 11:09:24,448 ERROR "GET /appeal/ HTTP/1.1" 500 125081
2023-01-10 11:10:02,671 ERROR Internal Server Error: /appeal/
Traceback (most recent call last):
  File "/Library/Frameworks/Python.framework/Versions/3.10/lib/python3.10/site-packages/django/core/handlers/exception.py", line 55, in inner
    response = get_response(request)
  File "/Library/Frameworks/Python.framework/Versions/3.10/lib/python3.10/site-packages/django/core/handlers/base.py", line 220, in _get_response
    response = response.render()
  File "/Library/Frameworks/Python.framework/Versions/3.10/lib/python3.10/site-packages/django/template/response.py", line 114, in render
    self.content = self.rendered_content
  File "/Library/Frameworks/Python.framework/Versions/3.10/lib/python3.10/site-packages/django/template/response.py", line 92, in rendered_content
    return template.render(context, self._request)
  File "/Library/Frameworks/Python.framework/Versions/3.10/lib/python3.10/site-packages/django/template/backends/django.py", line 62, in render
    return self.template.render(context)
  File "/Library/Frameworks/Python.framework/Versions/3.10/lib/python3.10/site-packages/django/template/base.py", line 175, in render
    return self._render(context)
  File "/Library/Frameworks/Python.framework/Versions/3.10/lib/python3.10/site-packages/django/template/base.py", line 167, in _render
    return self.nodelist.render(context)
  File "/Library/Frameworks/Python.framework/Versions/3.10/lib/python3.10/site-packages/django/template/base.py", line 1000, in render
    return SafeString("".join([node.render_annotated(context) for node in self]))
  File "/Library/Frameworks/Python.framework/Versions/3.10/lib/python3.10/site-packages/django/template/base.py", line 1000, in <listcomp>
    return SafeString("".join([node.render_annotated(context) for node in self]))
  File "/Library/Frameworks/Python.framework/Versions/3.10/lib/python3.10/site-packages/django/template/base.py", line 958, in render_annotated
    return self.render(context)
  File "/Library/Frameworks/Python.framework/Versions/3.10/lib/python3.10/site-packages/django/template/library.py", line 239, in render
    output = self.func(*resolved_args, **resolved_kwargs)
  File "/Library/Frameworks/Python.framework/Versions/3.10/lib/python3.10/site-packages/webpack_loader/templatetags/webpack_loader.py", line 12, in render_bundle
    tags = utils.get_as_tags(bundle_name, extension=extension, config=config, attrs=attrs)
  File "/Library/Frameworks/Python.framework/Versions/3.10/lib/python3.10/site-packages/webpack_loader/utils.py", line 62, in get_as_tags
    bundle = _get_bundle(bundle_name, extension, config)
  File "/Library/Frameworks/Python.framework/Versions/3.10/lib/python3.10/site-packages/webpack_loader/utils.py", line 40, in _get_bundle
    bundle = get_loader(config).get_bundle(bundle_name)
  File "/Library/Frameworks/Python.framework/Versions/3.10/lib/python3.10/site-packages/webpack_loader/loader.py", line 96, in get_bundle
    raise WebpackError(error)
webpack_loader.exceptions.WebpackError: 
            ModuleNotFoundError in 
            Module not found: Error: Can't resolve 'path' in '/Users/deniskanukov/online_reception_of_appeals/mysite/frontend/node_modules/convert-source-map'

BREAKING CHANGE: webpack < 5 used to include polyfills for node.js core modules by default.
This is no longer the case. Verify if you need this module and configure a polyfill for it.

If you want to include a polyfill, you need to:
	- add a fallback 'resolve.fallback: { "path": require.resolve("path-browserify") }'
	- install 'path-browserify'
If you don't want to include a polyfill, you can use an empty module like this:
	resolve.fallback: { "path": false }
            
2023-01-10 11:10:02,679 ERROR "GET /appeal/ HTTP/1.1" 500 125080
2023-01-10 11:10:03,476 WARNING Not Found: /appeal/<%= BASE_URL %>favicon.ico
2023-01-10 11:10:03,477 WARNING "GET /appeal/%3C%=%20BASE_URL%20%%3Efavicon.ico HTTP/1.1" 404 6044
2023-01-10 11:10:03,622 WARNING Not Found: /appeal/<%= BASE_URL %>favicon.ico
2023-01-10 11:10:03,623 WARNING "GET /appeal/%3C%=%20BASE_URL%20%%3Efavicon.ico HTTP/1.1" 404 6044
2023-01-10 11:10:03,729 WARNING Not Found: /appeal/<%= BASE_URL %>favicon.ico
2023-01-10 11:10:03,730 WARNING "GET /appeal/%3C%=%20BASE_URL%20%%3Efavicon.ico HTTP/1.1" 404 6044
2023-01-10 11:10:10,109 WARNING Not Found: /appeal/<%= BASE_URL %>favicon.ico
2023-01-10 11:10:10,110 WARNING "GET /appeal/%3C%=%20BASE_URL%20%%3Efavicon.ico HTTP/1.1" 404 6044
2023-01-10 11:10:17,699 WARNING Not Found: /appeal/<%= BASE_URL %>favicon.ico
2023-01-10 11:10:17,701 WARNING "GET /appeal/%3C%=%20BASE_URL%20%%3Efavicon.ico HTTP/1.1" 404 6044
2023-01-10 11:10:18,714 WARNING Not Found: /appeal/<%= BASE_URL %>favicon.ico
2023-01-10 11:10:18,715 WARNING "GET /appeal/%3C%=%20BASE_URL%20%%3Efavicon.ico HTTP/1.1" 404 6044
2023-01-10 11:18:51,479 WARNING Not Found: /media/images/IMG_2540.original.jpg}
2023-01-10 11:18:51,481 WARNING Not Found: /media/images/IMG_2539.original.jpg}
2023-01-10 11:18:51,482 WARNING "GET /media/images/IMG_2539.original.jpg%7D HTTP/1.1" 404 5622
2023-01-10 11:18:51,483 WARNING "GET /media/images/IMG_2540.original.jpg%7D HTTP/1.1" 404 5622
2023-01-10 11:18:51,516 WARNING Not Found: /media/images/IMG_2541.original.jpg}
2023-01-10 11:18:51,517 WARNING Not Found: /media/images/IMG_2538.original.jpg}
2023-01-10 11:18:51,518 WARNING Not Found: /media/images/IMG_2556.original.jpg}
2023-01-10 11:18:51,519 WARNING "GET /media/images/IMG_2541.original.jpg%7D HTTP/1.1" 404 5622
2023-01-10 11:18:51,520 WARNING "GET /media/images/IMG_2556.original.jpg%7D HTTP/1.1" 404 5622
2023-01-10 11:18:51,522 WARNING "GET /media/images/IMG_2538.original.jpg%7D HTTP/1.1" 404 5622
2023-01-10 11:18:53,835 WARNING Not Found: /media/original_images/terra-100-1.jpeg
2023-01-10 11:18:53,843 WARNING "GET /media/original_images/terra-100-1.jpeg HTTP/1.1" 404 5632
2023-01-10 11:19:15,958 WARNING Not Found: /media/images/IMG_2540.original.jpg}
2023-01-10 11:19:15,959 WARNING "GET /media/images/IMG_2540.original.jpg%7D HTTP/1.1" 404 5622
2023-01-10 11:19:16,008 WARNING Not Found: /media/images/IMG_2539.original.jpg}
2023-01-10 11:19:16,013 WARNING "GET /media/images/IMG_2539.original.jpg%7D HTTP/1.1" 404 5622
2023-01-10 11:19:16,016 WARNING Not Found: /media/images/IMG_2538.original.jpg}
2023-01-10 11:19:16,019 WARNING "GET /media/images/IMG_2538.original.jpg%7D HTTP/1.1" 404 5622
2023-01-10 11:19:16,021 WARNING Not Found: /media/images/IMG_2556.original.jpg}
2023-01-10 11:19:16,025 WARNING Not Found: /media/images/IMG_2541.original.jpg}
2023-01-10 11:19:16,031 WARNING "GET /media/images/IMG_2541.original.jpg%7D HTTP/1.1" 404 5622
2023-01-10 11:19:16,032 WARNING "GET /media/images/IMG_2556.original.jpg%7D HTTP/1.1" 404 5622
2023-01-10 11:19:21,269 WARNING Not Found: /media/images/IMG_2539.original.jpg}
2023-01-10 11:19:21,274 WARNING "GET /media/images/IMG_2539.original.jpg%7D HTTP/1.1" 404 5622
2023-01-10 11:19:21,275 WARNING Not Found: /media/images/IMG_2541.original.jpg}
2023-01-10 11:19:21,277 WARNING Not Found: /media/images/IMG_2540.original.jpg}
2023-01-10 11:19:21,277 WARNING Not Found: /media/images/IMG_2538.original.jpg}
2023-01-10 11:19:21,280 WARNING Not Found: /media/images/IMG_2556.original.jpg}
2023-01-10 11:19:21,280 WARNING "GET /media/images/IMG_2541.original.jpg%7D HTTP/1.1" 404 5622
2023-01-10 11:19:21,280 WARNING "GET /media/images/IMG_2540.original.jpg%7D HTTP/1.1" 404 5622
2023-01-10 11:19:21,318 WARNING "GET /media/images/IMG_2538.original.jpg%7D HTTP/1.1" 404 5622
2023-01-10 11:19:21,319 WARNING "GET /media/images/IMG_2556.original.jpg%7D HTTP/1.1" 404 5622
2023-01-10 11:19:24,597 WARNING Not Found: /media/images/IMG_2539.original.jpg}
2023-01-10 11:19:24,598 WARNING Not Found: /media/images/IMG_2540.original.jpg}
2023-01-10 11:19:24,599 WARNING "GET /media/images/IMG_2540.original.jpg%7D HTTP/1.1" 404 5622
2023-01-10 11:19:24,600 WARNING "GET /media/images/IMG_2539.original.jpg%7D HTTP/1.1" 404 5622
2023-01-10 11:19:24,611 WARNING Not Found: /media/images/IMG_2541.original.jpg}
2023-01-10 11:19:24,639 WARNING "GET /media/images/IMG_2541.original.jpg%7D HTTP/1.1" 404 5622
2023-01-10 11:19:24,647 WARNING Not Found: /media/images/IMG_2556.original.jpg}
2023-01-10 11:19:24,648 WARNING Not Found: /media/images/IMG_2538.original.jpg}
2023-01-10 11:19:24,649 WARNING "GET /media/images/IMG_2556.original.jpg%7D HTTP/1.1" 404 5622
2023-01-10 11:19:24,687 WARNING "GET /media/images/IMG_2538.original.jpg%7D HTTP/1.1" 404 5622
2023-01-10 11:19:27,355 WARNING Not Found: /media/images/IMG_2539.original.jpg}
2023-01-10 11:19:27,356 WARNING "GET /media/images/IMG_2539.original.jpg%7D HTTP/1.1" 404 5622
2023-01-10 11:19:27,358 WARNING Not Found: /media/images/IMG_2540.original.jpg}
2023-01-10 11:19:27,380 WARNING Not Found: /media/images/IMG_2541.original.jpg}
2023-01-10 11:19:27,383 WARNING Not Found: /media/images/IMG_2556.original.jpg}
2023-01-10 11:19:27,383 WARNING Not Found: /media/images/IMG_2538.original.jpg}
2023-01-10 11:19:27,390 WARNING "GET /media/images/IMG_2541.original.jpg%7D HTTP/1.1" 404 5622
2023-01-10 11:19:27,391 WARNING "GET /media/images/IMG_2540.original.jpg%7D HTTP/1.1" 404 5622
2023-01-10 11:19:27,393 WARNING "GET /media/images/IMG_2556.original.jpg%7D HTTP/1.1" 404 5622
2023-01-10 11:19:27,394 WARNING "GET /media/images/IMG_2538.original.jpg%7D HTTP/1.1" 404 5622
2023-01-10 11:21:50,670 WARNING Not Found: /appeal/<%= BASE_URL %>favicon.ico
2023-01-10 11:21:50,671 WARNING "GET /appeal/%3C%=%20BASE_URL%20%%3Efavicon.ico HTTP/1.1" 404 6044
2023-01-10 11:22:15,318 WARNING Not Found: /appeal/<%= BASE_URL %>favicon.ico
2023-01-10 11:22:15,319 WARNING "GET /appeal/%3C%=%20BASE_URL%20%%3Efavicon.ico HTTP/1.1" 404 6044
2023-01-10 11:22:21,923 WARNING Not Found: /appeal/<%= BASE_URL %>favicon.ico
2023-01-10 11:22:21,926 WARNING "GET /appeal/%3C%=%20BASE_URL%20%%3Efavicon.ico HTTP/1.1" 404 6044
2023-01-10 11:23:20,724 WARNING Not Found: /appeal/<%= BASE_URL %>favicon.ico
2023-01-10 11:23:20,725 WARNING "GET /appeal/%3C%=%20BASE_URL%20%%3Efavicon.ico HTTP/1.1" 404 6044
2023-01-10 11:23:49,853 WARNING Not Found: /appeal/<%= BASE_URL %>favicon.ico
2023-01-10 11:23:49,854 WARNING "GET /appeal/%3C%=%20BASE_URL%20%%3Efavicon.ico HTTP/1.1" 404 6044
2023-01-10 11:24:26,251 WARNING Not Found: /appeal/<%= BASE_URL %>favicon.ico
2023-01-10 11:24:26,252 WARNING "GET /appeal/%3C%=%20BASE_URL%20%%3Efavicon.ico HTTP/1.1" 404 6044
2023-01-10 11:24:33,124 WARNING Not Found: /appeal/<%= BASE_URL %>favicon.ico
2023-01-10 11:24:33,125 WARNING "GET /appeal/%3C%=%20BASE_URL%20%%3Efavicon.ico HTTP/1.1" 404 6044
2023-01-10 11:24:40,725 WARNING Not Found: /appeal/<%= BASE_URL %>favicon.ico
2023-01-10 11:24:40,726 WARNING "GET /appeal/%3C%=%20BASE_URL%20%%3Efavicon.ico HTTP/1.1" 404 6044
2023-01-10 11:25:16,597 WARNING Not Found: /appeal/<%= BASE_URL %>favicon.ico
2023-01-10 11:25:16,598 WARNING "GET /appeal/%3C%=%20BASE_URL%20%%3Efavicon.ico HTTP/1.1" 404 6044
2023-01-10 11:27:48,741 WARNING Not Found: /appeal/<%= BASE_URL %>favicon.ico
2023-01-10 11:27:48,742 WARNING "GET /appeal/%3C%=%20BASE_URL%20%%3Efavicon.ico HTTP/1.1" 404 6044
2023-01-14 17:02:28,447 ERROR Unsafe redirect to URL with protocol '127.0.0.1'
2023-01-14 17:02:28,532 WARNING Bad Request: /api/pay
2023-01-14 17:02:28,534 WARNING "GET /api/pay?value=1000 HTTP/1.1" 400 81600
2023-01-14 17:02:45,419 ERROR Unsafe redirect to URL with protocol '127.0.0.1'
2023-01-14 17:02:45,450 WARNING Bad Request: /api/pay
2023-01-14 17:02:45,452 WARNING "GET /api/pay?value=100 HTTP/1.1" 400 81590
2023-01-14 17:18:27,992 ERROR Internal Server Error: /api/appeal
Traceback (most recent call last):
  File "C:\Users\HP\PycharmProjects\git_push\venv\lib\site-packages\django\db\backends\utils.py", line 89, in _execute
    return self.cursor.execute(sql, params)
  File "C:\Users\HP\PycharmProjects\git_push\venv\lib\site-packages\django\db\backends\sqlite3\base.py", line 477, in execute
    return Database.Cursor.execute(self, query, params)
sqlite3.OperationalError: no such column: home_appeal.notes

The above exception was the direct cause of the following exception:

Traceback (most recent call last):
  File "C:\Users\HP\PycharmProjects\git_push\venv\lib\site-packages\django\core\handlers\exception.py", line 55, in inner
    response = get_response(request)
  File "C:\Users\HP\PycharmProjects\git_push\venv\lib\site-packages\django\core\handlers\base.py", line 197, in _get_response
    response = wrapped_callback(request, *callback_args, **callback_kwargs)
  File "C:\Users\HP\PycharmProjects\git_push\venv\lib\site-packages\django\views\decorators\csrf.py", line 54, in wrapped_view
    return view_func(*args, **kwargs)
  File "C:\Users\HP\PycharmProjects\git_push\venv\lib\site-packages\django\views\generic\base.py", line 84, in view
    return self.dispatch(request, *args, **kwargs)
  File "C:\Users\HP\PycharmProjects\git_push\venv\lib\site-packages\rest_framework\views.py", line 509, in dispatch
    response = self.handle_exception(exc)
  File "C:\Users\HP\PycharmProjects\git_push\venv\lib\site-packages\rest_framework\views.py", line 469, in handle_exception
    self.raise_uncaught_exception(exc)
  File "C:\Users\HP\PycharmProjects\git_push\venv\lib\site-packages\rest_framework\views.py", line 480, in raise_uncaught_exception
    raise exc
  File "C:\Users\HP\PycharmProjects\git_push\venv\lib\site-packages\rest_framework\views.py", line 506, in dispatch
    response = handler(request, *args, **kwargs)
  File "C:\Users\HP\PycharmProjects\git_push\online_reception_of_appeals\mysite\home\views.py", line 155, in get
    return Response(serializer.data)
  File "C:\Users\HP\PycharmProjects\git_push\venv\lib\site-packages\rest_framework\serializers.py", line 768, in data
    ret = super().data
  File "C:\Users\HP\PycharmProjects\git_push\venv\lib\site-packages\rest_framework\serializers.py", line 253, in data
    self._data = self.to_representation(self.instance)
  File "C:\Users\HP\PycharmProjects\git_push\venv\lib\site-packages\rest_framework\serializers.py", line 686, in to_representation
    return [
  File "C:\Users\HP\PycharmProjects\git_push\venv\lib\site-packages\django\db\models\query.py", line 320, in __iter__
    self._fetch_all()
  File "C:\Users\HP\PycharmProjects\git_push\venv\lib\site-packages\django\db\models\query.py", line 1507, in _fetch_all
    self._result_cache = list(self._iterable_class(self))
  File "C:\Users\HP\PycharmProjects\git_push\venv\lib\site-packages\django\db\models\query.py", line 57, in __iter__
    results = compiler.execute_sql(
  File "C:\Users\HP\PycharmProjects\git_push\venv\lib\site-packages\django\db\models\sql\compiler.py", line 1361, in execute_sql
    cursor.execute(sql, params)
  File "C:\Users\HP\PycharmProjects\git_push\venv\lib\site-packages\django\db\backends\utils.py", line 103, in execute
    return super().execute(sql, params)
  File "C:\Users\HP\PycharmProjects\git_push\venv\lib\site-packages\django\db\backends\utils.py", line 67, in execute
    return self._execute_with_wrappers(
  File "C:\Users\HP\PycharmProjects\git_push\venv\lib\site-packages\django\db\backends\utils.py", line 80, in _execute_with_wrappers
    return executor(sql, params, many, context)
  File "C:\Users\HP\PycharmProjects\git_push\venv\lib\site-packages\django\db\backends\utils.py", line 84, in _execute
    with self.db.wrap_database_errors:
  File "C:\Users\HP\PycharmProjects\git_push\venv\lib\site-packages\django\db\utils.py", line 91, in __exit__
    raise dj_exc_value.with_traceback(traceback) from exc_value
  File "C:\Users\HP\PycharmProjects\git_push\venv\lib\site-packages\django\db\backends\utils.py", line 89, in _execute
    return self.cursor.execute(sql, params)
  File "C:\Users\HP\PycharmProjects\git_push\venv\lib\site-packages\django\db\backends\sqlite3\base.py", line 477, in execute
    return Database.Cursor.execute(self, query, params)
django.db.utils.OperationalError: no such column: home_appeal.notes
2023-01-14 17:18:28,048 ERROR "GET /api/appeal HTTP/1.1" 500 165871
2023-01-14 17:18:28,349 WARNING Not Found: /appeal/<%= BASE_URL %>favicon.ico
2023-01-14 17:18:28,355 WARNING "GET /appeal/%3C%=%20BASE_URL%20%%3Efavicon.ico HTTP/1.1" 404 6044
2023-01-14 18:13:00,526 ERROR Internal Server Error: /api/pay
Traceback (most recent call last):
  File "C:\Users\HP\PycharmProjects\git_push\venv\lib\site-packages\django\core\handlers\exception.py", line 55, in inner
    response = get_response(request)
  File "C:\Users\HP\PycharmProjects\git_push\venv\lib\site-packages\django\core\handlers\base.py", line 220, in _get_response
    response = response.render()
  File "C:\Users\HP\PycharmProjects\git_push\venv\lib\site-packages\django\template\response.py", line 114, in render
    self.content = self.rendered_content
  File "C:\Users\HP\PycharmProjects\git_push\venv\lib\site-packages\rest_framework\response.py", line 55, in rendered_content
    assert renderer, ".accepted_renderer not set on Response"
AssertionError: .accepted_renderer not set on Response
2023-01-14 18:13:00,535 ERROR "GET /api/pay?value=250 HTTP/1.1" 500 72204
2023-01-14 18:13:43,482 ERROR Internal Server Error: /api/pay
Traceback (most recent call last):
  File "C:\Users\HP\PycharmProjects\git_push\venv\lib\site-packages\django\core\handlers\exception.py", line 55, in inner
    response = get_response(request)
  File "C:\Users\HP\PycharmProjects\git_push\venv\lib\site-packages\django\core\handlers\base.py", line 220, in _get_response
    response = response.render()
  File "C:\Users\HP\PycharmProjects\git_push\venv\lib\site-packages\django\template\response.py", line 114, in render
    self.content = self.rendered_content
  File "C:\Users\HP\PycharmProjects\git_push\venv\lib\site-packages\rest_framework\response.py", line 55, in rendered_content
    assert renderer, ".accepted_renderer not set on Response"
AssertionError: .accepted_renderer not set on Response
2023-01-14 18:13:43,489 ERROR "GET /api/pay?value=250 HTTP/1.1" 500 72341
2023-01-14 18:14:37,895 ERROR Internal Server Error: /api/pay
Traceback (most recent call last):
  File "C:\Users\HP\PycharmProjects\git_push\venv\lib\site-packages\django\core\handlers\exception.py", line 55, in inner
    response = get_response(request)
  File "C:\Users\HP\PycharmProjects\git_push\venv\lib\site-packages\django\core\handlers\base.py", line 220, in _get_response
    response = response.render()
  File "C:\Users\HP\PycharmProjects\git_push\venv\lib\site-packages\django\template\response.py", line 114, in render
    self.content = self.rendered_content
  File "C:\Users\HP\PycharmProjects\git_push\venv\lib\site-packages\rest_framework\response.py", line 55, in rendered_content
    assert renderer, ".accepted_renderer not set on Response"
AssertionError: .accepted_renderer not set on Response
2023-01-14 18:14:37,903 ERROR "GET /api/pay?value=100 HTTP/1.1" 500 69291
2023-01-14 18:15:11,580 ERROR Internal Server Error: /api/pay
Traceback (most recent call last):
  File "C:\Users\HP\PycharmProjects\git_push\venv\lib\site-packages\django\core\handlers\exception.py", line 55, in inner
    response = get_response(request)
  File "C:\Users\HP\PycharmProjects\git_push\venv\lib\site-packages\django\core\handlers\base.py", line 197, in _get_response
    response = wrapped_callback(request, *callback_args, **callback_kwargs)
  File "C:\Users\HP\PycharmProjects\git_push\venv\lib\site-packages\django\views\generic\base.py", line 84, in view
    return self.dispatch(request, *args, **kwargs)
  File "C:\Users\HP\PycharmProjects\git_push\venv\lib\site-packages\django\views\generic\base.py", line 119, in dispatch
    return handler(request, *args, **kwargs)
  File "C:\Users\HP\PycharmProjects\git_push\online_reception_of_appeals\mysite\home\payments.py", line 28, in get
    return JsonResponse(response)
  File "C:\Users\HP\PycharmProjects\git_push\venv\lib\site-packages\django\http\response.py", line 648, in __init__
    raise TypeError(
TypeError: In order to allow non-dict objects to be serialized set the safe parameter to False.
2023-01-14 18:15:11,591 ERROR "GET /api/pay?value=100 HTTP/1.1" 500 79583
2023-01-15 15:53:21,134 WARNING Not Found: /js/chunk-vendors.js
2023-01-15 15:53:21,141 WARNING Not Found: /js/app.js
2023-01-15 15:53:21,142 WARNING "GET /js/chunk-vendors.js HTTP/1.1" 404 6147
2023-01-15 15:53:21,145 WARNING "GET /js/app.js HTTP/1.1" 404 6117
2023-01-15 15:54:22,998 ERROR Internal Server Error: /api/appeal
Traceback (most recent call last):
  File "C:\Users\HP\PycharmProjects\git_push\venv\lib\site-packages\django\db\backends\utils.py", line 89, in _execute
    return self.cursor.execute(sql, params)
  File "C:\Users\HP\PycharmProjects\git_push\venv\lib\site-packages\django\db\backends\sqlite3\base.py", line 477, in execute
    return Database.Cursor.execute(self, query, params)
sqlite3.OperationalError: no such column: home_appeal.notes

The above exception was the direct cause of the following exception:

Traceback (most recent call last):
  File "C:\Users\HP\PycharmProjects\git_push\venv\lib\site-packages\django\core\handlers\exception.py", line 55, in inner
    response = get_response(request)
  File "C:\Users\HP\PycharmProjects\git_push\venv\lib\site-packages\django\core\handlers\base.py", line 197, in _get_response
    response = wrapped_callback(request, *callback_args, **callback_kwargs)
  File "C:\Users\HP\PycharmProjects\git_push\venv\lib\site-packages\django\views\decorators\csrf.py", line 54, in wrapped_view
    return view_func(*args, **kwargs)
  File "C:\Users\HP\PycharmProjects\git_push\venv\lib\site-packages\django\views\generic\base.py", line 84, in view
    return self.dispatch(request, *args, **kwargs)
  File "C:\Users\HP\PycharmProjects\git_push\venv\lib\site-packages\rest_framework\views.py", line 509, in dispatch
    response = self.handle_exception(exc)
  File "C:\Users\HP\PycharmProjects\git_push\venv\lib\site-packages\rest_framework\views.py", line 469, in handle_exception
    self.raise_uncaught_exception(exc)
  File "C:\Users\HP\PycharmProjects\git_push\venv\lib\site-packages\rest_framework\views.py", line 480, in raise_uncaught_exception
    raise exc
  File "C:\Users\HP\PycharmProjects\git_push\venv\lib\site-packages\rest_framework\views.py", line 506, in dispatch
    response = handler(request, *args, **kwargs)
  File "C:\Users\HP\PycharmProjects\git_push\online_reception_of_appeals\mysite\home\views.py", line 155, in get
    return Response(serializer.data)
  File "C:\Users\HP\PycharmProjects\git_push\venv\lib\site-packages\rest_framework\serializers.py", line 768, in data
    ret = super().data
  File "C:\Users\HP\PycharmProjects\git_push\venv\lib\site-packages\rest_framework\serializers.py", line 253, in data
    self._data = self.to_representation(self.instance)
  File "C:\Users\HP\PycharmProjects\git_push\venv\lib\site-packages\rest_framework\serializers.py", line 686, in to_representation
    return [
  File "C:\Users\HP\PycharmProjects\git_push\venv\lib\site-packages\django\db\models\query.py", line 320, in __iter__
    self._fetch_all()
  File "C:\Users\HP\PycharmProjects\git_push\venv\lib\site-packages\django\db\models\query.py", line 1507, in _fetch_all
    self._result_cache = list(self._iterable_class(self))
  File "C:\Users\HP\PycharmProjects\git_push\venv\lib\site-packages\django\db\models\query.py", line 57, in __iter__
    results = compiler.execute_sql(
  File "C:\Users\HP\PycharmProjects\git_push\venv\lib\site-packages\django\db\models\sql\compiler.py", line 1361, in execute_sql
    cursor.execute(sql, params)
  File "C:\Users\HP\PycharmProjects\git_push\venv\lib\site-packages\django\db\backends\utils.py", line 103, in execute
    return super().execute(sql, params)
  File "C:\Users\HP\PycharmProjects\git_push\venv\lib\site-packages\django\db\backends\utils.py", line 67, in execute
    return self._execute_with_wrappers(
  File "C:\Users\HP\PycharmProjects\git_push\venv\lib\site-packages\django\db\backends\utils.py", line 80, in _execute_with_wrappers
    return executor(sql, params, many, context)
  File "C:\Users\HP\PycharmProjects\git_push\venv\lib\site-packages\django\db\backends\utils.py", line 84, in _execute
    with self.db.wrap_database_errors:
  File "C:\Users\HP\PycharmProjects\git_push\venv\lib\site-packages\django\db\utils.py", line 91, in __exit__
    raise dj_exc_value.with_traceback(traceback) from exc_value
  File "C:\Users\HP\PycharmProjects\git_push\venv\lib\site-packages\django\db\backends\utils.py", line 89, in _execute
    return self.cursor.execute(sql, params)
  File "C:\Users\HP\PycharmProjects\git_push\venv\lib\site-packages\django\db\backends\sqlite3\base.py", line 477, in execute
    return Database.Cursor.execute(self, query, params)
django.db.utils.OperationalError: no such column: home_appeal.notes
2023-01-15 15:54:23,031 ERROR "GET /api/appeal HTTP/1.1" 500 165871
2023-01-15 15:59:55,889 WARNING Forbidden: /api/appeal
2023-01-15 15:59:55,891 WARNING "GET /api/appeal HTTP/1.1" 403 26
2023-01-15 16:00:20,179 ERROR Internal Server Error: /api/user
Traceback (most recent call last):
  File "C:\Users\HP\PycharmProjects\git_push\venv\lib\site-packages\django\core\handlers\exception.py", line 55, in inner
    response = get_response(request)
  File "C:\Users\HP\PycharmProjects\git_push\venv\lib\site-packages\django\core\handlers\base.py", line 197, in _get_response
    response = wrapped_callback(request, *callback_args, **callback_kwargs)
  File "C:\Users\HP\PycharmProjects\git_push\venv\lib\site-packages\django\views\decorators\csrf.py", line 54, in wrapped_view
    return view_func(*args, **kwargs)
  File "C:\Users\HP\PycharmProjects\git_push\venv\lib\site-packages\django\views\generic\base.py", line 84, in view
    return self.dispatch(request, *args, **kwargs)
  File "C:\Users\HP\PycharmProjects\git_push\venv\lib\site-packages\rest_framework\views.py", line 509, in dispatch
    response = self.handle_exception(exc)
  File "C:\Users\HP\PycharmProjects\git_push\venv\lib\site-packages\rest_framework\views.py", line 469, in handle_exception
    self.raise_uncaught_exception(exc)
  File "C:\Users\HP\PycharmProjects\git_push\venv\lib\site-packages\rest_framework\views.py", line 480, in raise_uncaught_exception
    raise exc
  File "C:\Users\HP\PycharmProjects\git_push\venv\lib\site-packages\rest_framework\views.py", line 506, in dispatch
    response = handler(request, *args, **kwargs)
  File "C:\Users\HP\PycharmProjects\git_push\online_reception_of_appeals\mysite\home\views.py", line 195, in get
    'first_name': request.user.first_name,
AttributeError: 'AnonymousUser' object has no attribute 'first_name'
2023-01-15 16:00:20,189 ERROR "GET /api/user HTTP/1.1" 500 90924
2023-01-15 16:03:32,075 ERROR Internal Server Error: /api/appeal
Traceback (most recent call last):
  File "C:\Users\HP\PycharmProjects\git_push\venv\lib\site-packages\django\core\handlers\exception.py", line 55, in inner
    response = get_response(request)
  File "C:\Users\HP\PycharmProjects\git_push\venv\lib\site-packages\django\core\handlers\base.py", line 197, in _get_response
    response = wrapped_callback(request, *callback_args, **callback_kwargs)
  File "C:\Users\HP\PycharmProjects\git_push\venv\lib\site-packages\django\views\decorators\csrf.py", line 54, in wrapped_view
    return view_func(*args, **kwargs)
  File "C:\Users\HP\PycharmProjects\git_push\venv\lib\site-packages\django\views\generic\base.py", line 84, in view
    return self.dispatch(request, *args, **kwargs)
  File "C:\Users\HP\PycharmProjects\git_push\venv\lib\site-packages\rest_framework\views.py", line 509, in dispatch
    response = self.handle_exception(exc)
  File "C:\Users\HP\PycharmProjects\git_push\venv\lib\site-packages\rest_framework\views.py", line 469, in handle_exception
    self.raise_uncaught_exception(exc)
  File "C:\Users\HP\PycharmProjects\git_push\venv\lib\site-packages\rest_framework\views.py", line 480, in raise_uncaught_exception
    raise exc
  File "C:\Users\HP\PycharmProjects\git_push\venv\lib\site-packages\rest_framework\views.py", line 506, in dispatch
    response = handler(request, *args, **kwargs)
  File "C:\Users\HP\PycharmProjects\git_push\online_reception_of_appeals\mysite\home\views.py", line 152, in get
    print(request.user.COOKIES)
  File "C:\Users\HP\PycharmProjects\git_push\venv\lib\site-packages\django\utils\functional.py", line 259, in inner
    return func(self._wrapped, *args)
AttributeError: 'User' object has no attribute 'COOKIES'
2023-01-15 16:03:32,090 ERROR "GET /api/appeal HTTP/1.1" 500 97402
2023-01-15 16:10:17,210 ERROR Internal Server Error: /api/pay
Traceback (most recent call last):
  File "C:\Users\HP\PycharmProjects\git_push\venv\lib\site-packages\django\core\handlers\exception.py", line 55, in inner
    response = get_response(request)
  File "C:\Users\HP\PycharmProjects\git_push\venv\lib\site-packages\django\core\handlers\base.py", line 220, in _get_response
    response = response.render()
  File "C:\Users\HP\PycharmProjects\git_push\venv\lib\site-packages\django\template\response.py", line 114, in render
    self.content = self.rendered_content
  File "C:\Users\HP\PycharmProjects\git_push\venv\lib\site-packages\rest_framework\response.py", line 55, in rendered_content
    assert renderer, ".accepted_renderer not set on Response"
AssertionError: .accepted_renderer not set on Response
2023-01-15 16:10:17,218 ERROR "GET /api/pay?value=150 HTTP/1.1" 500 70244
2023-01-15 16:12:41,986 WARNING Forbidden: /api/user
2023-01-15 16:12:41,990 WARNING "GET /api/user HTTP/1.1" 403 26
2023-01-15 16:17:47,124 WARNING Method Not Allowed: /api/appeal
2023-01-15 16:17:47,128 WARNING "PATCH /api/appeal HTTP/1.1" 405 56
2023-01-15 16:18:14,861 WARNING Forbidden: /api/appeal
2023-01-15 16:18:14,863 WARNING "PATCH /api/appeal HTTP/1.1" 403 45
2023-01-15 16:18:27,372 WARNING Method Not Allowed: /api/appeal
2023-01-15 16:18:27,374 WARNING "PATCH /api/appeal HTTP/1.1" 405 56
2023-01-15 16:18:41,587 WARNING Method Not Allowed: /api/appeal
2023-01-15 16:18:41,590 WARNING "PATCH /api/appeal HTTP/1.1" 405 56
2023-01-15 16:20:14,622 WARNING Forbidden: /api/appeal
2023-01-15 16:20:14,625 WARNING "GET /api/appeal HTTP/1.1" 403 26
2023-01-15 16:21:15,015 WARNING Method Not Allowed: /api/appeal
2023-01-15 16:21:15,017 WARNING "PATCH /api/appeal HTTP/1.1" 405 56
2023-01-15 16:25:37,676 WARNING Method Not Allowed: /api/appeal
2023-01-15 16:25:37,679 WARNING "PATCH /api/appeal HTTP/1.1" 405 56
2023-01-15 16:25:56,688 WARNING Method Not Allowed: /api/appeal
2023-01-15 16:25:56,690 WARNING "PATCH /api/appeal HTTP/1.1" 405 56
2023-01-15 16:29:06,444 WARNING Not Found: /api/appeal/3
2023-01-15 16:29:06,447 WARNING "PATCH /api/appeal/3 HTTP/1.1" 404 50
2023-01-15 16:29:16,595 ERROR Internal Server Error: /api/appeal/7
Traceback (most recent call last):
  File "C:\Users\HP\PycharmProjects\git_push\venv\lib\site-packages\django\core\handlers\exception.py", line 55, in inner
    response = get_response(request)
  File "C:\Users\HP\PycharmProjects\git_push\venv\lib\site-packages\django\core\handlers\base.py", line 197, in _get_response
    response = wrapped_callback(request, *callback_args, **callback_kwargs)
  File "C:\Users\HP\PycharmProjects\git_push\venv\lib\site-packages\django\views\decorators\csrf.py", line 54, in wrapped_view
    return view_func(*args, **kwargs)
  File "C:\Users\HP\PycharmProjects\git_push\venv\lib\site-packages\django\views\generic\base.py", line 84, in view
    return self.dispatch(request, *args, **kwargs)
  File "C:\Users\HP\PycharmProjects\git_push\venv\lib\site-packages\rest_framework\views.py", line 509, in dispatch
    response = self.handle_exception(exc)
  File "C:\Users\HP\PycharmProjects\git_push\venv\lib\site-packages\rest_framework\views.py", line 469, in handle_exception
    self.raise_uncaught_exception(exc)
  File "C:\Users\HP\PycharmProjects\git_push\venv\lib\site-packages\rest_framework\views.py", line 480, in raise_uncaught_exception
    raise exc
  File "C:\Users\HP\PycharmProjects\git_push\venv\lib\site-packages\rest_framework\views.py", line 506, in dispatch
    response = handler(request, *args, **kwargs)
  File "C:\Users\HP\PycharmProjects\git_push\online_reception_of_appeals\mysite\home\views.py", line 178, in patch
    appeal.notes = request.data['notes']
KeyError: 'notes'
2023-01-15 16:29:16,604 ERROR "PATCH /api/appeal/7 HTTP/1.1" 500 92433
2023-01-15 16:29:43,844 WARNING Bad Request: /api/appeal/7
2023-01-15 16:29:43,846 WARNING "PATCH /api/appeal/7 HTTP/1.1" 400 20
2023-01-15 16:31:31,980 ERROR Internal Server Error: /api/appeal/7
Traceback (most recent call last):
  File "C:\Users\HP\PycharmProjects\git_push\venv\lib\site-packages\django\core\handlers\exception.py", line 55, in inner
    response = get_response(request)
  File "C:\Users\HP\PycharmProjects\git_push\venv\lib\site-packages\django\core\handlers\base.py", line 197, in _get_response
    response = wrapped_callback(request, *callback_args, **callback_kwargs)
  File "C:\Users\HP\PycharmProjects\git_push\venv\lib\site-packages\django\views\decorators\csrf.py", line 54, in wrapped_view
    return view_func(*args, **kwargs)
  File "C:\Users\HP\PycharmProjects\git_push\venv\lib\site-packages\django\views\generic\base.py", line 84, in view
    return self.dispatch(request, *args, **kwargs)
  File "C:\Users\HP\PycharmProjects\git_push\venv\lib\site-packages\rest_framework\views.py", line 509, in dispatch
    response = self.handle_exception(exc)
  File "C:\Users\HP\PycharmProjects\git_push\venv\lib\site-packages\rest_framework\views.py", line 469, in handle_exception
    self.raise_uncaught_exception(exc)
  File "C:\Users\HP\PycharmProjects\git_push\venv\lib\site-packages\rest_framework\views.py", line 480, in raise_uncaught_exception
    raise exc
  File "C:\Users\HP\PycharmProjects\git_push\venv\lib\site-packages\rest_framework\views.py", line 506, in dispatch
    response = handler(request, *args, **kwargs)
  File "C:\Users\HP\PycharmProjects\git_push\online_reception_of_appeals\mysite\home\views.py", line 178, in patch
    appeal.notes = request.data['notes']
KeyError: 'notes'
2023-01-15 16:31:31,987 ERROR "PATCH /api/appeal/7 HTTP/1.1" 500 92433
